Workbook
Name SegmentaçãodeDados_Equipe: #N/A
Name SegmentaçãodeDados_Piloto: #N/A

Sheet Dummy Table
F1: posições de chegada | AD1: desempate
A2: Rank | B2: Driver | C2: Nationality | D2: Team | E2: Point | F2: 1 | G2: 2 | H2: 3 | I2: 4 | J2: 5 | K2: 6 | L2: 7 | M2: 8 | N2: 9 | O2: 10 | P2: 11 | Q2: 12 | R2: 13 | S2: 14 | T2: 15 | U2: 16 | V2: 17 | W2: 18 | X2: 19 | Y2: 20 | Z2: 21 | AA2: 22 | AB2: 23 | AC2: 24 | AD2: p1 | AE2: p2 | AF2: p3 | AG2: p4 | AH2: p5 | AI2: p6 | AJ2: p7 | AK2: p8 | AL2: p9 | AM2: p10 | AN2: p11 | AO2: p12 | AP2: p13 | AQ2: p14 | AR2: p15 | AS2: p16 | AT2: p17 | AU2: p18 | AV2: p19 | AW2: p20 | AX2: p21 | AY2: p22 | AZ2: p23 | BA2: p24 | BB2: Number | BC2: Number
A3: =IF(B3<>"",RANK(E3,E$3:E$30)+SUM(AD3:BB3),"") -> 6 | B3: =IF('Equipes e Pilotos'!C3<>"",'Equipes e Pilotos'!C3,"") -> Lando Norris | C3: =IF(B3<>"",VLOOKUP(B3,'Equipes e Pilotos'!$C$3:$F$30,3,FALSE),"") -> Inglaterra | D3: =IF(B3<>"",VLOOKUP(B3,'Equipes e Pilotos'!$C$3:$F$30,4,FALSE),"") -> McLaren | E3: =IF(B3<>"",SUMIF(Resultados!C:C,B3,Resultados!F:F),"") -> 201 | F3: =IF(B3<>"",SUMPRODUCT((Resultados!$B$1:$B$602=1)*(Resultados!$C$1:$C$602=B3)*1),"") -> 3 | G3: =IF(B3<>"",SUMPRODUCT((Resultados!$B$1:$B$602=2)*(Resultados!$C$1:$C$602=B3)*1),"") -> 2 | H3: =IF(B3<>"",SUMPRODUCT((Resultados!$B$1:$B$602=3)*(Resultados!$C$1:$C$602=B3)*1),"") -> 4 | I3: =IF(B3<>"",SUMPRODUCT((Resultados!$B$1:$B$602=4)*(Resultados!$C$1:$C$602=B3)*1),"") -> 3 | J3: =IF(B3<>"",SUMPRODUCT((Resultados!$B$1:$B$602=5)*(Resultados!$C$1:$C$602=B3)*1),"") -> 2 | K3: =IF(B3<>"",SUMPRODUCT((Resultados!$B$1:$B$602=6)*(Resultados!$C$1:$C$602=B3)*1),"") -> 0 | L3: =IF(B3<>"",SUMPRODUCT((Resultados!$B$1:$B$602=7)*(Resultados!$C$1:$C$602=B3)*1),"") -> 2 | M3: =IF(B3<>"",SUMPRODUCT((Resultados!$B$1:$B$602=8)*(Resultados!$C$1:$C$602=B3)*1),"") -> 0 | N3: =IF(B3<>"",SUMPRODUCT((Resultados!$B$1:$B$602=9)*(Resultados!$C$1:$C$602=B3)*1),"") -> 1 | O3: =IF(B3<>"",SUMPRODUCT((Resultados!$B$1:$B$602=10)*(Resultados!$C$1:$C$602=B3)*1),"") -> 0 | P3: =IF(B3<>"",SUMPRODUCT((Resultados!$B$1:$B$602=11)*(Resultados!$C$1:$C$602=B3)*1),"") -> 0 | Q3: =IF(B3<>"",SUMPRODUCT((Resultados!$B$1:$B$602=12)*(Resultados!$C$1:$C$602=B3)*1),"") -> 0 | R3: =IF(B3<>"",SUMPRODUCT((Resultados!$B$1:$B$602=13)*(Resultados!$C$1:$C$602=B3)*1),"") -> 0 | S3: =IF(B3<>"",SUMPRODUCT((Resultados!$B$1:$B$602=14)*(Resultados!$C$1:$C$602=B3)*1),"") -> 0 | T3: =IF(B3<>"",SUMPRODUCT((Resultados!$B$1:$B$602=15)*(Resultados!$C$1:$C$602=B3)*1),"") -> 0 | U3: =IF(B3<>"",SUMPRODUCT((Resultados!$B$1:$B$602=16)*(Resultados!$C$1:$C$602=B3)*1),"") -> 0 | V3: =IF(B3<>"",SUMPRODUCT((Resultados!$B$1:$B$602=17)*(Resultados!$C$1:$C$602=B3)*1),"") -> 0 | W3: =IF(B3<>"",SUMPRODUCT((Resultados!$B$1:$B$602=18)*(Resultados!$C$1:$C$602=B3)*1),"") -> 1 | X3: =IF(B3<>"",SUMPRODUCT((Resultados!$B$1:$B$602=19)*(Resultados!$C$1:$C$602=B3)*1),"") -> 2 | Y3: =IF(B3<>"",SUMPRODUCT((Resultados!$B$1:$B$602=20)*(Resultados!$C$1:$C$602=B3)*1),"") -> 1 | Z3: =IF(B3<>"",SUMPRODUCT((Resultados!$B$1:$B$602=21)*(Resultados!$C$1:$C$602=B3)*1),"") -> 0 | AA3: =IF(B3<>"",SUMPRODUCT((Resultados!$B$1:$B$602=22)*(Resultados!$C$1:$C$602=B3)*1),"") -> 0 | AB3: =IF(B3<>"",SUMPRODUCT((Resultados!$B$1:$B$602=23)*(Resultados!$C$1:$C$602=B3)*1),"") -> 0 | AC3: =IF(B3<>"",SUMPRODUCT((Resultados!$B$1:$B$602=24)*(Resultados!$C$1:$C$602=B3)*1),"") -> 0 | AD3: =IF(B3<>"",SUMPRODUCT(($E$3:$E$30=E3)*($F$3:$F$30>F3)),"") -> 0 | AE3: =IF(B3<>"",SUMPRODUCT(($E$3:$E$30=E3)*($F$3:$F$30=F3)*($G$3:$G$30>G3)),"") -> 0 | AF3: =IF(B3<>"",SUMPRODUCT(($E$3:$E$30=E3)*($F$3:$F$30=F3)*($G$3:$G$30=G3)*($H$3:$H$30>H3)),"") -> 0 | AG3: =IF(B3<>"",SUMPRODUCT(($E$3:$E$30=E3)*($F$3:$F$30=F3)*($G$3:$G$30=G3)*($H$3:$H$30=H3)*($I$3:$I$30>I3)),"") -> 0 | AH3: =IF(B3<>"",SUMPRODUCT(($E$3:$E$30=E3)*($F$3:$F$30=F3)*($G$3:$G$30=G3)*($H$3:$H$30=H3)*($I$3:$I$30=I3)*($J$3:$J$30>J3)),"") -> 0 | AI3: =IF(B3<>"",SUMPRODUCT(($E$3:$E$30=E3)*($F$3:$F$30=F3)*($G$3:$G$30=G3)*($H$3:$H$30=H3)*($I$3:$I$30=I3)*($J$3:$J$30=J3)*($K$3:$K$30>K3)),"") -> 0 | AJ3: =IF(B3<>"",SUMPRODUCT(($E$3:$E$30=E3)*($F$3:$F$30=F3)*($G$3:$G$30=G3)*($H$3:$H$30=H3)*($I$3:$I$30=I3)*($J$3:$J$30=J3)*($K$3:$K$30=K3)*($L$3:$L$30>L3)),"") -> 0 | AK3: =IF(B3<>"",SUMPRODUCT(($E$3:$E$30=E3)*($F$3:$F$30=F3)*($G$3:$G$30=G3)*($H$3:$H$30=H3)*($I$3:$I$30=I3)*($J$3:$J$30=J3)*($K$3:$K$30=K3)*($L$3:$L$30=L3)*($M$3:$M$30>M3)),"") -> 0 | AL3: =IF(B3<>"",SUMPRODUCT(($E$3:$E$30=E3)*($F$3:$F$30=F3)*($G$3:$G$30=G3)*($H$3:$H$30=H3)*($I$3:$I$30=I3)*($J$3:$J$30=J3)*($K$3:$K$30=K3)*($L$3:$L$30=L3)*($M$3:$M$30=M3)*($N$3:$N$30>N3)),"") -> 0 | AM3: =IF(B3<>"",SUMPRODUCT(($E$3:$E$30=E3)*($F$3:$F$30=F3)*($G$3:$G$30=G3)*($H$3:$H$30=H3)*($I$3:$I$30=I3)*($J$3:$J$30=J3)*($K$3:$K$30=K3)*($L$3:$L$30=L3)*($M$3:$M$30=M3)*($N$3:$N$30=N3)*($O$3:$O$30>O3)),"") -> 0 | AN3: =IF(B3<>"",SUMPRODUCT(($E$3:$E$30=E3)*($F$3:$F$30=F3)*($G$3:$G$30=G3)*($H$3:$H$30=H3)*($I$3:$I$30=I3)*($J$3:$J$30=J3)*($K$3:$K$30=K3)*($L$3:$L$30=L3)*($M$3:$M$30=M3)*($N$3:$N$30=N3)*($O$3:$O$30=O3)*($P$3:$P$30>P3)),"") -> 0 | AO3: =IF(B3<>"",SUMPRODUCT(($E$3:$E$30=E3)*($F$3:$F$30=F3)*($G$3:$G$30=G3)*($H$3:$H$30=H3)*($I$3:$I$30=I3)*($J$3:$J$30=J3)*($K$3:$K$30=K3)*($L$3:$L$30=L3)*($M$3:$M$30=M3)*($N$3:$N$30=N3)*($O$3:$O$30=O3)*($P$3:$P$30=P3)*($Q$3:$Q$30>Q3)),"") -> 0 | AP3: =IF(B3<>"",SUMPRODUCT(($E$3:$E$30=E3)*($F$3:$F$30=F3)*($G$3:$G$30=G3)*($H$3:$H$30=H3)*($I$3:$I$30=I3)*($J$3:$J$30=J3)*($K$3:$K$30=K3)*($L$3:$L$30=L3)*($M$3:$M$30=M3)*($N$3:$N$30=N3)*($O$3:$O$30=O3)*($P$3:$P$30=P3)*($Q$3:$Q$30=Q3)*($R$3:$R$30>R3)),"") -> 0 | AQ3: =IF(B3<>"",SUMPRODUCT(($E$3:$E$30=E3)*($F$3:$F$30=F3)*($G$3:$G$30=G3)*($H$3:$H$30=H3)*($I$3:$I$30=I3)*($J$3:$J$30=J3)*($K$3:$K$30=K3)*($L$3:$L$30=L3)*($M$3:$M$30=M3)*($N$3:$N$30=N3)*($O$3:$O$30=O3)*($P$3:$P$30=P3)*($Q$3:$Q$30=Q3)*($R$3:$R$30=R3)*($S$3:$S$30>S3)),"") -> 0 | AR3: =IF(B3<>"",SUMPRODUCT(($E$3:$E$30=E3)*($F$3:$F$30=F3)*($G$3:$G$30=G3)*($H$3:$H$30=H3)*($I$3:$I$30=I3)*($J$3:$J$30=J3)*($K$3:$K$30=K3)*($L$3:$L$30=L3)*($M$3:$M$30=M3)*($N$3:$N$30=N3)*($O$3:$O$30=O3)*($P$3:$P$30=P3)*($Q$3:$Q$30=Q3)*($R$3:$R$30=R3)*($S$3:$S$30=S3)*($T$3:$T$30>T3)),"") -> 0 | AS3: =IF(B3<>"",SUMPRODUCT(($E$3:$E$30=E3)*($F$3:$F$30=F3)*($G$3:$G$30=G3)*($H$3:$H$30=H3)*($I$3:$I$30=I3)*($J$3:$J$30=J3)*($K$3:$K$30=K3)*($L$3:$L$30=L3)*($M$3:$M$30=M3)*($N$3:$N$30=N3)*($O$3:$O$30=O3)*($P$3:$P$30=P3)*($Q$3:$Q$30=Q3)*($R$3:$R$30=R3)*($S$3:$S$30=S3)*($T$3:$T$30=T3)*($U$3:$U$30>U3)),"") -> 0 | AT3: =IF(B3<>"",SUMPRODUCT(($E$3:$E$30=E3)*($F$3:$F$30=F3)*($G$3:$G$30=G3)*($H$3:$H$30=H3)*($I$3:$I$30=I3)*($J$3:$J$30=J3)*($K$3:$K$30=K3)*($L$3:$L$30=L3)*($M$3:$M$30=M3)*($N$3:$N$30=N3)*($O$3:$O$30=O3)*($P$3:$P$30=P3)*($Q$3:$Q$30=Q3)*($R$3:$R$30=R3)*($S$3:$S$30=S3)*($T$3:$T$30=T3)*($U$3:$U$30=U3)*($V$3:$V$30>V3)),"") -> 0 | AU3: =IF(B3<>"",SUMPRODUCT(($E$3:$E$30=E3)*($F$3:$F$30=F3)*($G$3:$G$30=G3)*($H$3:$H$30=H3)*($I$3:$I$30=I3)*($J$3:$J$30=J3)*($K$3:$K$30=K3)*($L$3:$L$30=L3)*($M$3:$M$30=M3)*($N$3:$N$30=N3)*($O$3:$O$30=O3)*($P$3:$P$30=P3)*($Q$3:$Q$30=Q3)*($R$3:$R$30=R3)*($S$3:$S$30=S3)*($T$3:$T$30=T3)*($U$3:$U$30=U3)*($V$3:$V$30=V3)*($W$3:$W$30>W3)),"") -> 0 | AV3: =IF(B3<>"",SUMPRODUCT(($E$3:$E$30=E3)*($F$3:$F$30=F3)*($G$3:$G$30=G3)*($H$3:$H$30=H3)*($I$3:$I$30=I3)*($J$3:$J$30=J3)*($K$3:$K$30=K3)*($L$3:$L$30=L3)*($M$3:$M$30=M3)*($N$3:$N$30=N3)*($O$3:$O$30=O3)*($P$3:$P$30=P3)*($Q$3:$Q$30=Q3)*($R$3:$R$30=R3)*($S$3:$S$30=S3)*($T$3:$T$30=T3)*($U$3:$U$30=U3)*($V$3:$V$30=V3)*($W$3:$W$30=W3)*($X$3:$X$30>X3)),"") -> 0 | AW3: =IF(B3<>"",SUMPRODUCT(($E$3:$E$30=E3)*($F$3:$F$30=F3)*($G$3:$G$30=G3)*($H$3:$H$30=H3)*($I$3:$I$30=I3)*($J$3:$J$30=J3)*($K$3:$K$30=K3)*($L$3:$L$30=L3)*($M$3:$M$30=M3)*($N$3:$N$30=N3)*($O$3:$O$30=O3)*($P$3:$P$30=P3)*($Q$3:$Q$30=Q3)*($R$3:$R$30=R3)*($S$3:$S$30=S3)*($T$3:$T$30=T3)*($U$3:$U$30=U3)*($V$3:$V$30=V3)*($W$3:$W$30=W3)*($X$3:$X$30=X3)*($Y$3:$Y$30>Y3)),"") -> 0 | AX3: =IF(B3<>"",SUMPRODUCT(($E$3:$E$30=E3)*($F$3:$F$30=F3)*($G$3:$G$30=G3)*($H$3:$H$30=H3)*($I$3:$I$30=I3)*($J$3:$J$30=J3)*($K$3:$K$30=K3)*($L$3:$L$30=L3)*($M$3:$M$30=M3)*($N$3:$N$30=N3)*($O$3:$O$30=O3)*($P$3:$P$30=P3)*($Q$3:$Q$30=Q3)*($R$3:$R$30=R3)*($S$3:$S$30=S3)*($T$3:$T$30=T3)*($U$3:$U$30=U3)*($V$3:$V$30=V3)*($W$3:$W$30=W3)*($X$3:$X$30=X3)*($Y$3:$Y$30=Y3)*($Z$3:$Z$30>Z3)),"") -> 0 | AY3: =IF(B3<>"",SUMPRODUCT(($E$3:$E$30=E3)*($F$3:$F$30=F3)*($G$3:$G$30=G3)*($H$3:$H$30=H3)*($I$3:$I$30=I3)*($J$3:$J$30=J3)*($K$3:$K$30=K3)*($L$3:$L$30=L3)*($M$3:$M$30=M3)*($N$3:$N$30=N3)*($O$3:$O$30=O3)*($P$3:$P$30=P3)*($Q$3:$Q$30=Q3)*($R$3:$R$30=R3)*($S$3:$S$30=S3)*($T$3:$T$30=T3)*($U$3:$U$30=U3)*($V$3:$V$30=V3)*($W$3:$W$30=W3)*($X$3:$X$30=X3)*($Y$3:$Y$30=Y3)*($Z$3:$Z$30=Z3)*($AA$3:$AA$30>AA3)),"") -> 0 | AZ3: =IF(B3<>"",SUMPRODUCT(($E$3:$E$30=E3)*($F$3:$F$30=F3)*($G$3:$G$30=G3)*($H$3:$H$30=H3)*($I$3:$I$30=I3)*($J$3:$J$30=J3)*($K$3:$K$30=K3)*($L$3:$L$30=L3)*($M$3:$M$30=M3)*($N$3:$N$30=N3)*($O$3:$O$30=O3)*($P$3:$P$30=P3)*($Q$3:$Q$30=Q3)*($R$3:$R$30=R3)*($S$3:$S$30=S3)*($T$3:$T$30=T3)*($U$3:$U$30=U3)*($V$3:$V$30=V3)*($W$3:$W$30=W3)*($X$3:$X$30=X3)*($Y$3:$Y$30=Y3)*($Z$3:$Z$30=Z3)*($AA$3:$AA$30=AA3)*($AB$3:$AB$30>AB3)),"") -> 0 | BA3: =IF(B3<>"",SUMPRODUCT(($E$3:$E$30=E3)*($F$3:$F$30=F3)*($G$3:$G$30=G3)*($H$3:$H$30=H3)*($I$3:$I$30=I3)*($J$3:$J$30=J3)*($K$3:$K$30=K3)*($L$3:$L$30=L3)*($M$3:$M$30=M3)*($N$3:$N$30=N3)*($O$3:$O$30=O3)*($P$3:$P$30=P3)*($Q$3:$Q$30=Q3)*($R$3:$R$30=R3)*($S$3:$S$30=S3)*($T$3:$T$30=T3)*($U$3:$U$30=U3)*($V$3:$V$30=V3)*($W$3:$W$30=W3)*($X$3:$X$30=X3)*($Y$3:$Y$30=Y3)*($Z$3:$Z$30=Z3)*($AA$3:$AA$30=AA3)*($AB$3:$AB$30=AB3)*($AC$3:$AC$30>AC3)),"") -> 0 | BB3: =IF(B3<>"",SUMPRODUCT(($E$3:$E$30=E3)*($F$3:$F$30=F3)*($G$3:$G$30=G3)*($H$3:$H$30=H3)*($I$3:$I$30=I3)*($J$3:$J$30=J3)*($K$3:$K$30=K3)*($L$3:$L$30=L3)*($M$3:$M$30=M3)*($N$3:$N$30=N3)*($O$3:$O$30=O3)*($P$3:$P$30=P3)*($Q$3:$Q$30=Q3)*($R$3:$R$30=R3)*($S$3:$S$30=S3)*($T$3:$T$30=T3)*($U$3:$U$30=U3)*($V$3:$V$30=V3)*($W$3:$W$30=W3)*($X$3:$X$30=X3)*($Y$3:$Y$30=Y3)*($Z$3:$Z$30=Z3)*($AA$3:$AA$30=AA3)*($AB$3:$AB$30=AB3)*($AC$3:$AC$30=AC3)*($BC$3:$BC$30<BC3)),"") -> 0 | BC3: =IF(B3<>"",'Equipes e Pilotos'!B3,"") -> 1
A4: =IF(B4<>"",RANK(E4,E$3:E$30)+SUM(AD4:BB4),"") -> 7 | B4: =IF('Equipes e Pilotos'!C4<>"",'Equipes e Pilotos'!C4,"") -> Oscar Piastri | C4: =IF(B4<>"",VLOOKUP(B4,'Equipes e Pilotos'!$C$3:$F$30,3,FALSE),"") -> Austrália | D4: =IF(B4<>"",VLOOKUP(B4,'Equipes e Pilotos'!$C$3:$F$30,4,FALSE),"") -> McLaren | E4: =IF(B4<>"",SUMIF(Resultados!C:C,B4,Resultados!F:F),"") -> 138 | F4: =IF(B4<>"",SUMPRODUCT((Resultados!$B$1:$B$602=1)*(Resultados!$C$1:$C$602=B4)*1),"") -> 0 | G4: =IF(B4<>"",SUMPRODUCT((Resultados!$B$1:$B$602=2)*(Resultados!$C$1:$C$602=B4)*1),"") -> 2 | H4: =IF(B4<>"",SUMPRODUCT((Resultados!$B$1:$B$602=3)*(Resultados!$C$1:$C$602=B4)*1),"") -> 1 | I4: =IF(B4<>"",SUMPRODUCT((Resultados!$B$1:$B$602=4)*(Resultados!$C$1:$C$602=B4)*1),"") -> 3 | J4: =IF(B4<>"",SUMPRODUCT((Resultados!$B$1:$B$602=5)*(Resultados!$C$1:$C$602=B4)*1),"") -> 4 | K4: =IF(B4<>"",SUMPRODUCT((Resultados!$B$1:$B$602=6)*(Resultados!$C$1:$C$602=B4)*1),"") -> 3 | L4: =IF(B4<>"",SUMPRODUCT((Resultados!$B$1:$B$602=7)*(Resultados!$C$1:$C$602=B4)*1),"") -> 1 | M4: =IF(B4<>"",SUMPRODUCT((Resultados!$B$1:$B$602=8)*(Resultados!$C$1:$C$602=B4)*1),"") -> 1 | N4: =IF(B4<>"",SUMPRODUCT((Resultados!$B$1:$B$602=9)*(Resultados!$C$1:$C$602=B4)*1),"") -> 0 | O4: =IF(B4<>"",SUMPRODUCT((Resultados!$B$1:$B$602=10)*(Resultados!$C$1:$C$602=B4)*1),"") -> 0 | P4: =IF(B4<>"",SUMPRODUCT((Resultados!$B$1:$B$602=11)*(Resultados!$C$1:$C$602=B4)*1),"") -> 2 | Q4: =IF(B4<>"",SUMPRODUCT((Resultados!$B$1:$B$602=12)*(Resultados!$C$1:$C$602=B4)*1),"") -> 0 | R4: =IF(B4<>"",SUMPRODUCT((Resultados!$B$1:$B$602=13)*(Resultados!$C$1:$C$602=B4)*1),"") -> 1 | S4: =IF(B4<>"",SUMPRODUCT((Resultados!$B$1:$B$602=14)*(Resultados!$C$1:$C$602=B4)*1),"") -> 0 | T4: =IF(B4<>"",SUMPRODUCT((Resultados!$B$1:$B$602=15)*(Resultados!$C$1:$C$602=B4)*1),"") -> 0 | U4: =IF(B4<>"",SUMPRODUCT((Resultados!$B$1:$B$602=16)*(Resultados!$C$1:$C$602=B4)*1),"") -> 0 | V4: =IF(B4<>"",SUMPRODUCT((Resultados!$B$1:$B$602=17)*(Resultados!$C$1:$C$602=B4)*1),"") -> 0 | W4: =IF(B4<>"",SUMPRODUCT((Resultados!$B$1:$B$602=18)*(Resultados!$C$1:$C$602=B4)*1),"") -> 0 | X4: =IF(B4<>"",SUMPRODUCT((Resultados!$B$1:$B$602=19)*(Resultados!$C$1:$C$602=B4)*1),"") -> 1 | Y4: =IF(B4<>"",SUMPRODUCT((Resultados!$B$1:$B$602=20)*(Resultados!$C$1:$C$602=B4)*1),"") -> 1 | Z4: =IF(B4<>"",SUMPRODUCT((Resultados!$B$1:$B$602=21)*(Resultados!$C$1:$C$602=B4)*1),"") -> 1 | AA4: =IF(B4<>"",SUMPRODUCT((Resultados!$B$1:$B$602=22)*(Resultados!$C$1:$C$602=B4)*1),"") -> 0 | AB4: =IF(B4<>"",SUMPRODUCT((Resultados!$B$1:$B$602=23)*(Resultados!$C$1:$C$602=B4)*1),"") -> 0 | AC4: =IF(B4<>"",SUMPRODUCT((Resultados!$B$1:$B$602=24)*(Resultados!$C$1:$C$602=B4)*1),"") -> 0 | AD4: =IF(B4<>"",SUMPRODUCT(($E$3:$E$30=E4)*($F$3:$F$30>F4)),"") -> 0 | AE4: =IF(B4<>"",SUMPRODUCT(($E$3:$E$30=E4)*($F$3:$F$30=F4)*($G$3:$G$30>G4)),"") -> 0 | AF4: =IF(B4<>"",SUMPRODUCT(($E$3:$E$30=E4)*($F$3:$F$30=F4)*($G$3:$G$30=G4)*($H$3:$H$30>H4)),"") -> 0 | AG4: =IF(B4<>"",SUMPRODUCT(($E$3:$E$30=E4)*($F$3:$F$30=F4)*($G$3:$G$30=G4)*($H$3:$H$30=H4)*($I$3:$I$30>I4)),"") -> 0 | AH4: =IF(B4<>"",SUMPRODUCT(($E$3:$E$30=E4)*($F$3:$F$30=F4)*($G$3:$G$30=G4)*($H$3:$H$30=H4)*($I$3:$I$30=I4)*($J$3:$J$30>J4)),"") -> 0 | AI4: =IF(B4<>"",SUMPRODUCT(($E$3:$E$30=E4)*($F$3:$F$30=F4)*($G$3:$G$30=G4)*($H$3:$H$30=H4)*($I$3:$I$30=I4)*($J$3:$J$30=J4)*($K$3:$K$30>K4)),"") -> 0 | AJ4: =IF(B4<>"",SUMPRODUCT(($E$3:$E$30=E4)*($F$3:$F$30=F4)*($G$3:$G$30=G4)*($H$3:$H$30=H4)*($I$3:$I$30=I4)*($J$3:$J$30=J4)*($K$3:$K$30=K4)*($L$3:$L$30>L4)),"") -> 0 | AK4: =IF(B4<>"",SUMPRODUCT(($E$3:$E$30=E4)*($F$3:$F$30=F4)*($G$3:$G$30=G4)*($H$3:$H$30=H4)*($I$3:$I$30=I4)*($J$3:$J$30=J4)*($K$3:$K$30=K4)*($L$3:$L$30=L4)*($M$3:$M$30>M4)),"") -> 0 | AL4: =IF(B4<>"",SUMPRODUCT(($E$3:$E$30=E4)*($F$3:$F$30=F4)*($G$3:$G$30=G4)*($H$3:$H$30=H4)*($I$3:$I$30=I4)*($J$3:$J$30=J4)*($K$3:$K$30=K4)*($L$3:$L$30=L4)*($M$3:$M$30=M4)*($N$3:$N$30>N4)),"") -> 0 | AM4: =IF(B4<>"",SUMPRODUCT(($E$3:$E$30=E4)*($F$3:$F$30=F4)*($G$3:$G$30=G4)*($H$3:$H$30=H4)*($I$3:$I$30=I4)*($J$3:$J$30=J4)*($K$3:$K$30=K4)*($L$3:$L$30=L4)*($M$3:$M$30=M4)*($N$3:$N$30=N4)*($O$3:$O$30>O4)),"") -> 0 | AN4: =IF(B4<>"",SUMPRODUCT(($E$3:$E$30=E4)*($F$3:$F$30=F4)*($G$3:$G$30=G4)*($H$3:$H$30=H4)*($I$3:$I$30=I4)*($J$3:$J$30=J4)*($K$3:$K$30=K4)*($L$3:$L$30=L4)*($M$3:$M$30=M4)*($N$3:$N$30=N4)*($O$3:$O$30=O4)*($P$3:$P$30>P4)),"") -> 0 | AO4: =IF(B4<>"",SUMPRODUCT(($E$3:$E$30=E4)*($F$3:$F$30=F4)*($G$3:$G$30=G4)*($H$3:$H$30=H4)*($I$3:$I$30=I4)*($J$3:$J$30=J4)*($K$3:$K$30=K4)*($L$3:$L$30=L4)*($M$3:$M$30=M4)*($N$3:$N$30=N4)*($O$3:$O$30=O4)*($P$3:$P$30=P4)*($Q$3:$Q$30>Q4)),"") -> 0 | AP4: =IF(B4<>"",SUMPRODUCT(($E$3:$E$30=E4)*($F$3:$F$30=F4)*($G$3:$G$30=G4)*($H$3:$H$30=H4)*($I$3:$I$30=I4)*($J$3:$J$30=J4)*($K$3:$K$30=K4)*($L$3:$L$30=L4)*($M$3:$M$30=M4)*($N$3:$N$30=N4)*($O$3:$O$30=O4)*($P$3:$P$30=P4)*($Q$3:$Q$30=Q4)*($R$3:$R$30>R4)),"") -> 0 | AQ4: =IF(B4<>"",SUMPRODUCT(($E$3:$E$30=E4)*($F$3:$F$30=F4)*($G$3:$G$30=G4)*($H$3:$H$30=H4)*($I$3:$I$30=I4)*($J$3:$J$30=J4)*($K$3:$K$30=K4)*($L$3:$L$30=L4)*($M$3:$M$30=M4)*($N$3:$N$30=N4)*($O$3:$O$30=O4)*($P$3:$P$30=P4)*($Q$3:$Q$30=Q4)*($R$3:$R$30=R4)*($S$3:$S$30>S4)),"") -> 0 | AR4: =IF(B4<>"",SUMPRODUCT(($E$3:$E$30=E4)*($F$3:$F$30=F4)*($G$3:$G$30=G4)*($H$3:$H$30=H4)*($I$3:$I$30=I4)*($J$3:$J$30=J4)*($K$3:$K$30=K4)*($L$3:$L$30=L4)*($M$3:$M$30=M4)*($N$3:$N$30=N4)*($O$3:$O$30=O4)*($P$3:$P$30=P4)*($Q$3:$Q$30=Q4)*($R$3:$R$30=R4)*($S$3:$S$30=S4)*($T$3:$T$30>T4)),"") -> 0 | AS4: =IF(B4<>"",SUMPRODUCT(($E$3:$E$30=E4)*($F$3:$F$30=F4)*($G$3:$G$30=G4)*($H$3:$H$30=H4)*($I$3:$I$30=I4)*($J$3:$J$30=J4)*($K$3:$K$30=K4)*($L$3:$L$30=L4)*($M$3:$M$30=M4)*($N$3:$N$30=N4)*($O$3:$O$30=O4)*($P$3:$P$30=P4)*($Q$3:$Q$30=Q4)*($R$3:$R$30=R4)*($S$3:$S$30=S4)*($T$3:$T$30=T4)*($U$3:$U$30>U4)),"") -> 0 | AT4: =IF(B4<>"",SUMPRODUCT(($E$3:$E$30=E4)*($F$3:$F$30=F4)*($G$3:$G$30=G4)*($H$3:$H$30=H4)*($I$3:$I$30=I4)*($J$3:$J$30=J4)*($K$3:$K$30=K4)*($L$3:$L$30=L4)*($M$3:$M$30=M4)*($N$3:$N$30=N4)*($O$3:$O$30=O4)*($P$3:$P$30=P4)*($Q$3:$Q$30=Q4)*($R$3:$R$30=R4)*($S$3:$S$30=S4)*($T$3:$T$30=T4)*($U$3:$U$30=U4)*($V$3:$V$30>V4)),"") -> 0 | AU4: =IF(B4<>"",SUMPRODUCT(($E$3:$E$30=E4)*($F$3:$F$30=F4)*($G$3:$G$30=G4)*($H$3:$H$30=H4)*($I$3:$I$30=I4)*($J$3:$J$30=J4)*($K$3:$K$30=K4)*($L$3:$L$30=L4)*($M$3:$M$30=M4)*($N$3:$N$30=N4)*($O$3:$O$30=O4)*($P$3:$P$30=P4)*($Q$3:$Q$30=Q4)*($R$3:$R$30=R4)*($S$3:$S$30=S4)*($T$3:$T$30=T4)*($U$3:$U$30=U4)*($V$3:$V$30=V4)*($W$3:$W$30>W4)),"") -> 0 | AV4: =IF(B4<>"",SUMPRODUCT(($E$3:$E$30=E4)*($F$3:$F$30=F4)*($G$3:$G$30=G4)*($H$3:$H$30=H4)*($I$3:$I$30=I4)*($J$3:$J$30=J4)*($K$3:$K$30=K4)*($L$3:$L$30=L4)*($M$3:$M$30=M4)*($N$3:$N$30=N4)*($O$3:$O$30=O4)*($P$3:$P$30=P4)*($Q$3:$Q$30=Q4)*($R$3:$R$30=R4)*($S$3:$S$30=S4)*($T$3:$T$30=T4)*($U$3:$U$30=U4)*($V$3:$V$30=V4)*($W$3:$W$30=W4)*($X$3:$X$30>X4)),"") -> 0 | AW4: =IF(B4<>"",SUMPRODUCT(($E$3:$E$30=E4)*($F$3:$F$30=F4)*($G$3:$G$30=G4)*($H$3:$H$30=H4)*($I$3:$I$30=I4)*($J$3:$J$30=J4)*($K$3:$K$30=K4)*($L$3:$L$30=L4)*($M$3:$M$30=M4)*($N$3:$N$30=N4)*($O$3:$O$30=O4)*($P$3:$P$30=P4)*($Q$3:$Q$30=Q4)*($R$3:$R$30=R4)*($S$3:$S$30=S4)*($T$3:$T$30=T4)*($U$3:$U$30=U4)*($V$3:$V$30=V4)*($W$3:$W$30=W4)*($X$3:$X$30=X4)*($Y$3:$Y$30>Y4)),"") -> 0 | AX4: =IF(B4<>"",SUMPRODUCT(($E$3:$E$30=E4)*($F$3:$F$30=F4)*($G$3:$G$30=G4)*($H$3:$H$30=H4)*($I$3:$I$30=I4)*($J$3:$J$30=J4)*($K$3:$K$30=K4)*($L$3:$L$30=L4)*($M$3:$M$30=M4)*($N$3:$N$30=N4)*($O$3:$O$30=O4)*($P$3:$P$30=P4)*($Q$3:$Q$30=Q4)*($R$3:$R$30=R4)*($S$3:$S$30=S4)*($T$3:$T$30=T4)*($U$3:$U$30=U4)*($V$3:$V$30=V4)*($W$3:$W$30=W4)*($X$3:$X$30=X4)*($Y$3:$Y$30=Y4)*($Z$3:$Z$30>Z4)),"") -> 0 | AY4: =IF(B4<>"",SUMPRODUCT(($E$3:$E$30=E4)*($F$3:$F$30=F4)*($G$3:$G$30=G4)*($H$3:$H$30=H4)*($I$3:$I$30=I4)*($J$3:$J$30=J4)*($K$3:$K$30=K4)*($L$3:$L$30=L4)*($M$3:$M$30=M4)*($N$3:$N$30=N4)*($O$3:$O$30=O4)*($P$3:$P$30=P4)*($Q$3:$Q$30=Q4)*($R$3:$R$30=R4)*($S$3:$S$30=S4)*($T$3:$T$30=T4)*($U$3:$U$30=U4)*($V$3:$V$30=V4)*($W$3:$W$30=W4)*($X$3:$X$30=X4)*($Y$3:$Y$30=Y4)*($Z$3:$Z$30=Z4)*($AA$3:$AA$30>AA4)),"") -> 0 | AZ4: =IF(B4<>"",SUMPRODUCT(($E$3:$E$30=E4)*($F$3:$F$30=F4)*($G$3:$G$30=G4)*($H$3:$H$30=H4)*($I$3:$I$30=I4)*($J$3:$J$30=J4)*($K$3:$K$30=K4)*($L$3:$L$30=L4)*($M$3:$M$30=M4)*($N$3:$N$30=N4)*($O$3:$O$30=O4)*($P$3:$P$30=P4)*($Q$3:$Q$30=Q4)*($R$3:$R$30=R4)*($S$3:$S$30=S4)*($T$3:$T$30=T4)*($U$3:$U$30=U4)*($V$3:$V$30=V4)*($W$3:$W$30=W4)*($X$3:$X$30=X4)*($Y$3:$Y$30=Y4)*($Z$3:$Z$30=Z4)*($AA$3:$AA$30=AA4)*($AB$3:$AB$30>AB4)),"") -> 0 | BA4: =IF(B4<>"",SUMPRODUCT(($E$3:$E$30=E4)*($F$3:$F$30=F4)*($G$3:$G$30=G4)*($H$3:$H$30=H4)*($I$3:$I$30=I4)*($J$3:$J$30=J4)*($K$3:$K$30=K4)*($L$3:$L$30=L4)*($M$3:$M$30=M4)*($N$3:$N$30=N4)*($O$3:$O$30=O4)*($P$3:$P$30=P4)*($Q$3:$Q$30=Q4)*($R$3:$R$30=R4)*($S$3:$S$30=S4)*($T$3:$T$30=T4)*($U$3:$U$30=U4)*($V$3:$V$30=V4)*($W$3:$W$30=W4)*($X$3:$X$30=X4)*($Y$3:$Y$30=Y4)*($Z$3:$Z$30=Z4)*($AA$3:$AA$30=AA4)*($AB$3:$AB$30=AB4)*($AC$3:$AC$30>AC4)),"") -> 0 | BB4: =IF(B4<>"",SUMPRODUCT(($E$3:$E$30=E4)*($F$3:$F$30=F4)*($G$3:$G$30=G4)*($H$3:$H$30=H4)*($I$3:$I$30=I4)*($J$3:$J$30=J4)*($K$3:$K$30=K4)*($L$3:$L$30=L4)*($M$3:$M$30=M4)*($N$3:$N$30=N4)*($O$3:$O$30=O4)*($P$3:$P$30=P4)*($Q$3:$Q$30=Q4)*($R$3:$R$30=R4)*($S$3:$S$30=S4)*($T$3:$T$30=T4)*($U$3:$U$30=U4)*($V$3:$V$30=V4)*($W$3:$W$30=W4)*($X$3:$X$30=X4)*($Y$3:$Y$30=Y4)*($Z$3:$Z$30=Z4)*($AA$3:$AA$30=AA4)*($AB$3:$AB$30=AB4)*($AC$3:$AC$30=AC4)*($BC$3:$BC$30<BC4)),"") -> 0 | BC4: =IF(B4<>"",'Equipes e Pilotos'!B4,"") -> 2
A5: =IF(B5<>"",RANK(E5,E$3:E$30)+SUM(AD5:BB5),"") -> 2 | B5: =IF('Equipes e Pilotos'!C5<>"",'Equipes e Pilotos'!C5,"") -> George Russell | C5: =IF(B5<>"",VLOOKUP(B5,'Equipes e Pilotos'!$C$3:$F$30,3,FALSE),"") -> Inglaterra | D5: =IF(B5<>"",VLOOKUP(B5,'Equipes e Pilotos'!$C$3:$F$30,4,FALSE),"") -> Mercedes | E5: =IF(B5<>"",SUMIF(Resultados!C:C,B5,Resultados!F:F),"") -> 238 | F5: =IF(B5<>"",SUMPRODUCT((Resultados!$B$1:$B$602=1)*(Resultados!$C$1:$C$602=B5)*1),"") -> 6 | G5: =IF(B5<>"",SUMPRODUCT((Resultados!$B$1:$B$602=2)*(Resultados!$C$1:$C$602=B5)*1),"") -> 4 | H5: =IF(B5<>"",SUMPRODUCT((Resultados!$B$1:$B$602=3)*(Resultados!$C$1:$C$602=B5)*1),"") -> 1 | I5: =IF(B5<>"",SUMPRODUCT((Resultados!$B$1:$B$602=4)*(Resultados!$C$1:$C$602=B5)*1),"") -> 4 | J5: =IF(B5<>"",SUMPRODUCT((Resultados!$B$1:$B$602=5)*(Resultados!$C$1:$C$602=B5)*1),"") -> 1 | K5: =IF(B5<>"",SUMPRODUCT((Resultados!$B$1:$B$602=6)*(Resultados!$C$1:$C$602=B5)*1),"") -> 0 | L5: =IF(B5<>"",SUMPRODUCT((Resultados!$B$1:$B$602=7)*(Resultados!$C$1:$C$602=B5)*1),"") -> 1 | M5: =IF(B5<>"",SUMPRODUCT((Resultados!$B$1:$B$602=8)*(Resultados!$C$1:$C$602=B5)*1),"") -> 0 | N5: =IF(B5<>"",SUMPRODUCT((Resultados!$B$1:$B$602=9)*(Resultados!$C$1:$C$602=B5)*1),"") -> 0 | O5: =IF(B5<>"",SUMPRODUCT((Resultados!$B$1:$B$602=10)*(Resultados!$C$1:$C$602=B5)*1),"") -> 0 | P5: =IF(B5<>"",SUMPRODUCT((Resultados!$B$1:$B$602=11)*(Resultados!$C$1:$C$602=B5)*1),"") -> 0 | Q5: =IF(B5<>"",SUMPRODUCT((Resultados!$B$1:$B$602=12)*(Resultados!$C$1:$C$602=B5)*1),"") -> 1 | R5: =IF(B5<>"",SUMPRODUCT((Resultados!$B$1:$B$602=13)*(Resultados!$C$1:$C$602=B5)*1),"") -> 1 | S5: =IF(B5<>"",SUMPRODUCT((Resultados!$B$1:$B$602=14)*(Resultados!$C$1:$C$602=B5)*1),"") -> 0 | T5: =IF(B5<>"",SUMPRODUCT((Resultados!$B$1:$B$602=15)*(Resultados!$C$1:$C$602=B5)*1),"") -> 0 | U5: =IF(B5<>"",SUMPRODUCT((Resultados!$B$1:$B$602=16)*(Resultados!$C$1:$C$602=B5)*1),"") -> 0 | V5: =IF(B5<>"",SUMPRODUCT((Resultados!$B$1:$B$602=17)*(Resultados!$C$1:$C$602=B5)*1),"") -> 0 | W5: =IF(B5<>"",SUMPRODUCT((Resultados!$B$1:$B$602=18)*(Resultados!$C$1:$C$602=B5)*1),"") -> 0 | X5: =IF(B5<>"",SUMPRODUCT((Resultados!$B$1:$B$602=19)*(Resultados!$C$1:$C$602=B5)*1),"") -> 1 | Y5: =IF(B5<>"",SUMPRODUCT((Resultados!$B$1:$B$602=20)*(Resultados!$C$1:$C$602=B5)*1),"") -> 1 | Z5: =IF(B5<>"",SUMPRODUCT((Resultados!$B$1:$B$602=21)*(Resultados!$C$1:$C$602=B5)*1),"") -> 0 | AA5: =IF(B5<>"",SUMPRODUCT((Resultados!$B$1:$B$602=22)*(Resultados!$C$1:$C$602=B5)*1),"") -> 1 | AB5: =IF(B5<>"",SUMPRODUCT((Resultados!$B$1:$B$602=23)*(Resultados!$C$1:$C$602=B5)*1),"") -> 0 | AC5: =IF(B5<>"",SUMPRODUCT((Resultados!$B$1:$B$602=24)*(Resultados!$C$1:$C$602=B5)*1),"") -> 0 | AD5: =IF(B5<>"",SUMPRODUCT(($E$3:$E$30=E5)*($F$3:$F$30>F5)),"") -> 0 | AE5: =IF(B5<>"",SUMPRODUCT(($E$3:$E$30=E5)*($F$3:$F$30=F5)*($G$3:$G$30>G5)),"") -> 0 | AF5: =IF(B5<>"",SUMPRODUCT(($E$3:$E$30=E5)*($F$3:$F$30=F5)*($G$3:$G$30=G5)*($H$3:$H$30>H5)),"") -> 0 | AG5: =IF(B5<>"",SUMPRODUCT(($E$3:$E$30=E5)*($F$3:$F$30=F5)*($G$3:$G$30=G5)*($H$3:$H$30=H5)*($I$3:$I$30>I5)),"") -> 0 | AH5: =IF(B5<>"",SUMPRODUCT(($E$3:$E$30=E5)*($F$3:$F$30=F5)*($G$3:$G$30=G5)*($H$3:$H$30=H5)*($I$3:$I$30=I5)*($J$3:$J$30>J5)),"") -> 0 | AI5: =IF(B5<>"",SUMPRODUCT(($E$3:$E$30=E5)*($F$3:$F$30=F5)*($G$3:$G$30=G5)*($H$3:$H$30=H5)*($I$3:$I$30=I5)*($J$3:$J$30=J5)*($K$3:$K$30>K5)),"") -> 0 | AJ5: =IF(B5<>"",SUMPRODUCT(($E$3:$E$30=E5)*($F$3:$F$30=F5)*($G$3:$G$30=G5)*($H$3:$H$30=H5)*($I$3:$I$30=I5)*($J$3:$J$30=J5)*($K$3:$K$30=K5)*($L$3:$L$30>L5)),"") -> 0 | AK5: =IF(B5<>"",SUMPRODUCT(($E$3:$E$30=E5)*($F$3:$F$30=F5)*($G$3:$G$30=G5)*($H$3:$H$30=H5)*($I$3:$I$30=I5)*($J$3:$J$30=J5)*($K$3:$K$30=K5)*($L$3:$L$30=L5)*($M$3:$M$30>M5)),"") -> 0 | AL5: =IF(B5<>"",SUMPRODUCT(($E$3:$E$30=E5)*($F$3:$F$30=F5)*($G$3:$G$30=G5)*($H$3:$H$30=H5)*($I$3:$I$30=I5)*($J$3:$J$30=J5)*($K$3:$K$30=K5)*($L$3:$L$30=L5)*($M$3:$M$30=M5)*($N$3:$N$30>N5)),"") -> 0 | AM5: =IF(B5<>"",SUMPRODUCT(($E$3:$E$30=E5)*($F$3:$F$30=F5)*($G$3:$G$30=G5)*($H$3:$H$30=H5)*($I$3:$I$30=I5)*($J$3:$J$30=J5)*($K$3:$K$30=K5)*($L$3:$L$30=L5)*($M$3:$M$30=M5)*($N$3:$N$30=N5)*($O$3:$O$30>O5)),"") -> 0 | AN5: =IF(B5<>"",SUMPRODUCT(($E$3:$E$30=E5)*($F$3:$F$30=F5)*($G$3:$G$30=G5)*($H$3:$H$30=H5)*($I$3:$I$30=I5)*($J$3:$J$30=J5)*($K$3:$K$30=K5)*($L$3:$L$30=L5)*($M$3:$M$30=M5)*($N$3:$N$30=N5)*($O$3:$O$30=O5)*($P$3:$P$30>P5)),"") -> 0 | AO5: =IF(B5<>"",SUMPRODUCT(($E$3:$E$30=E5)*($F$3:$F$30=F5)*($G$3:$G$30=G5)*($H$3:$H$30=H5)*($I$3:$I$30=I5)*($J$3:$J$30=J5)*($K$3:$K$30=K5)*($L$3:$L$30=L5)*($M$3:$M$30=M5)*($N$3:$N$30=N5)*($O$3:$O$30=O5)*($P$3:$P$30=P5)*($Q$3:$Q$30>Q5)),"") -> 0 | AP5: =IF(B5<>"",SUMPRODUCT(($E$3:$E$30=E5)*($F$3:$F$30=F5)*($G$3:$G$30=G5)*($H$3:$H$30=H5)*($I$3:$I$30=I5)*($J$3:$J$30=J5)*($K$3:$K$30=K5)*($L$3:$L$30=L5)*($M$3:$M$30=M5)*($N$3:$N$30=N5)*($O$3:$O$30=O5)*($P$3:$P$30=P5)*($Q$3:$Q$30=Q5)*($R$3:$R$30>R5)),"") -> 0 | AQ5: =IF(B5<>"",SUMPRODUCT(($E$3:$E$30=E5)*($F$3:$F$30=F5)*($G$3:$G$30=G5)*($H$3:$H$30=H5)*($I$3:$I$30=I5)*($J$3:$J$30=J5)*($K$3:$K$30=K5)*($L$3:$L$30=L5)*($M$3:$M$30=M5)*($N$3:$N$30=N5)*($O$3:$O$30=O5)*($P$3:$P$30=P5)*($Q$3:$Q$30=Q5)*($R$3:$R$30=R5)*($S$3:$S$30>S5)),"") -> 0 | AR5: =IF(B5<>"",SUMPRODUCT(($E$3:$E$30=E5)*($F$3:$F$30=F5)*($G$3:$G$30=G5)*($H$3:$H$30=H5)*($I$3:$I$30=I5)*($J$3:$J$30=J5)*($K$3:$K$30=K5)*($L$3:$L$30=L5)*($M$3:$M$30=M5)*($N$3:$N$30=N5)*($O$3:$O$30=O5)*($P$3:$P$30=P5)*($Q$3:$Q$30=Q5)*($R$3:$R$30=R5)*($S$3:$S$30=S5)*($T$3:$T$30>T5)),"") -> 0 | AS5: =IF(B5<>"",SUMPRODUCT(($E$3:$E$30=E5)*($F$3:$F$30=F5)*($G$3:$G$30=G5)*($H$3:$H$30=H5)*($I$3:$I$30=I5)*($J$3:$J$30=J5)*($K$3:$K$30=K5)*($L$3:$L$30=L5)*($M$3:$M$30=M5)*($N$3:$N$30=N5)*($O$3:$O$30=O5)*($P$3:$P$30=P5)*($Q$3:$Q$30=Q5)*($R$3:$R$30=R5)*($S$3:$S$30=S5)*($T$3:$T$30=T5)*($U$3:$U$30>U5)),"") -> 0 | AT5: =IF(B5<>"",SUMPRODUCT(($E$3:$E$30=E5)*($F$3:$F$30=F5)*($G$3:$G$30=G5)*($H$3:$H$30=H5)*($I$3:$I$30=I5)*($J$3:$J$30=J5)*($K$3:$K$30=K5)*($L$3:$L$30=L5)*($M$3:$M$30=M5)*($N$3:$N$30=N5)*($O$3:$O$30=O5)*($P$3:$P$30=P5)*($Q$3:$Q$30=Q5)*($R$3:$R$30=R5)*($S$3:$S$30=S5)*($T$3:$T$30=T5)*($U$3:$U$30=U5)*($V$3:$V$30>V5)),"") -> 0 | AU5: =IF(B5<>"",SUMPRODUCT(($E$3:$E$30=E5)*($F$3:$F$30=F5)*($G$3:$G$30=G5)*($H$3:$H$30=H5)*($I$3:$I$30=I5)*($J$3:$J$30=J5)*($K$3:$K$30=K5)*($L$3:$L$30=L5)*($M$3:$M$30=M5)*($N$3:$N$30=N5)*($O$3:$O$30=O5)*($P$3:$P$30=P5)*($Q$3:$Q$30=Q5)*($R$3:$R$30=R5)*($S$3:$S$30=S5)*($T$3:$T$30=T5)*($U$3:$U$30=U5)*($V$3:$V$30=V5)*($W$3:$W$30>W5)),"") -> 0 | AV5: =IF(B5<>"",SUMPRODUCT(($E$3:$E$30=E5)*($F$3:$F$30=F5)*($G$3:$G$30=G5)*($H$3:$H$30=H5)*($I$3:$I$30=I5)*($J$3:$J$30=J5)*($K$3:$K$30=K5)*($L$3:$L$30=L5)*($M$3:$M$30=M5)*($N$3:$N$30=N5)*($O$3:$O$30=O5)*($P$3:$P$30=P5)*($Q$3:$Q$30=Q5)*($R$3:$R$30=R5)*($S$3:$S$30=S5)*($T$3:$T$30=T5)*($U$3:$U$30=U5)*($V$3:$V$30=V5)*($W$3:$W$30=W5)*($X$3:$X$30>X5)),"") -> 0 | AW5: =IF(B5<>"",SUMPRODUCT(($E$3:$E$30=E5)*($F$3:$F$30=F5)*($G$3:$G$30=G5)*($H$3:$H$30=H5)*($I$3:$I$30=I5)*($J$3:$J$30=J5)*($K$3:$K$30=K5)*($L$3:$L$30=L5)*($M$3:$M$30=M5)*($N$3:$N$30=N5)*($O$3:$O$30=O5)*($P$3:$P$30=P5)*($Q$3:$Q$30=Q5)*($R$3:$R$30=R5)*($S$3:$S$30=S5)*($T$3:$T$30=T5)*($U$3:$U$30=U5)*($V$3:$V$30=V5)*($W$3:$W$30=W5)*($X$3:$X$30=X5)*($Y$3:$Y$30>Y5)),"") -> 0 | AX5: =IF(B5<>"",SUMPRODUCT(($E$3:$E$30=E5)*($F$3:$F$30=F5)*($G$3:$G$30=G5)*($H$3:$H$30=H5)*($I$3:$I$30=I5)*($J$3:$J$30=J5)*($K$3:$K$30=K5)*($L$3:$L$30=L5)*($M$3:$M$30=M5)*($N$3:$N$30=N5)*($O$3:$O$30=O5)*($P$3:$P$30=P5)*($Q$3:$Q$30=Q5)*($R$3:$R$30=R5)*($S$3:$S$30=S5)*($T$3:$T$30=T5)*($U$3:$U$30=U5)*($V$3:$V$30=V5)*($W$3:$W$30=W5)*($X$3:$X$30=X5)*($Y$3:$Y$30=Y5)*($Z$3:$Z$30>Z5)),"") -> 0 | AY5: =IF(B5<>"",SUMPRODUCT(($E$3:$E$30=E5)*($F$3:$F$30=F5)*($G$3:$G$30=G5)*($H$3:$H$30=H5)*($I$3:$I$30=I5)*($J$3:$J$30=J5)*($K$3:$K$30=K5)*($L$3:$L$30=L5)*($M$3:$M$30=M5)*($N$3:$N$30=N5)*($O$3:$O$30=O5)*($P$3:$P$30=P5)*($Q$3:$Q$30=Q5)*($R$3:$R$30=R5)*($S$3:$S$30=S5)*($T$3:$T$30=T5)*($U$3:$U$30=U5)*($V$3:$V$30=V5)*($W$3:$W$30=W5)*($X$3:$X$30=X5)*($Y$3:$Y$30=Y5)*($Z$3:$Z$30=Z5)*($AA$3:$AA$30>AA5)),"") -> 0 | AZ5: =IF(B5<>"",SUMPRODUCT(($E$3:$E$30=E5)*($F$3:$F$30=F5)*($G$3:$G$30=G5)*($H$3:$H$30=H5)*($I$3:$I$30=I5)*($J$3:$J$30=J5)*($K$3:$K$30=K5)*($L$3:$L$30=L5)*($M$3:$M$30=M5)*($N$3:$N$30=N5)*($O$3:$O$30=O5)*($P$3:$P$30=P5)*($Q$3:$Q$30=Q5)*($R$3:$R$30=R5)*($S$3:$S$30=S5)*($T$3:$T$30=T5)*($U$3:$U$30=U5)*($V$3:$V$30=V5)*($W$3:$W$30=W5)*($X$3:$X$30=X5)*($Y$3:$Y$30=Y5)*($Z$3:$Z$30=Z5)*($AA$3:$AA$30=AA5)*($AB$3:$AB$30>AB5)),"") -> 0 | BA5: =IF(B5<>"",SUMPRODUCT(($E$3:$E$30=E5)*($F$3:$F$30=F5)*($G$3:$G$30=G5)*($H$3:$H$30=H5)*($I$3:$I$30=I5)*($J$3:$J$30=J5)*($K$3:$K$30=K5)*($L$3:$L$30=L5)*($M$3:$M$30=M5)*($N$3:$N$30=N5)*($O$3:$O$30=O5)*($P$3:$P$30=P5)*($Q$3:$Q$30=Q5)*($R$3:$R$30=R5)*($S$3:$S$30=S5)*($T$3:$T$30=T5)*($U$3:$U$30=U5)*($V$3:$V$30=V5)*($W$3:$W$30=W5)*($X$3:$X$30=X5)*($Y$3:$Y$30=Y5)*($Z$3:$Z$30=Z5)*($AA$3:$AA$30=AA5)*($AB$3:$AB$30=AB5)*($AC$3:$AC$30>AC5)),"") -> 0 | BB5: =IF(B5<>"",SUMPRODUCT(($E$3:$E$30=E5)*($F$3:$F$30=F5)*($G$3:$G$30=G5)*($H$3:$H$30=H5)*($I$3:$I$30=I5)*($J$3:$J$30=J5)*($K$3:$K$30=K5)*($L$3:$L$30=L5)*($M$3:$M$30=M5)*($N$3:$N$30=N5)*($O$3:$O$30=O5)*($P$3:$P$30=P5)*($Q$3:$Q$30=Q5)*($R$3:$R$30=R5)*($S$3:$S$30=S5)*($T$3:$T$30=T5)*($U$3:$U$30=U5)*($V$3:$V$30=V5)*($W$3:$W$30=W5)*($X$3:$X$30=X5)*($Y$3:$Y$30=Y5)*($Z$3:$Z$30=Z5)*($AA$3:$AA$30=AA5)*($AB$3:$AB$30=AB5)*($AC$3:$AC$30=AC5)*($BC$3:$BC$30<BC5)),"") -> 0 | BC5: =IF(B5<>"",'Equipes e Pilotos'!B5,"") -> 3
A6: =IF(B6<>"",RANK(E6,E$3:E$30)+SUM(AD6:BB6),"") -> 1 | B6: =IF('Equipes e Pilotos'!C6<>"",'Equipes e Pilotos'!C6,"") -> Kimi Antonelli | C6: =IF(B6<>"",VLOOKUP(B6,'Equipes e Pilotos'!$C$3:$F$30,3,FALSE),"") -> Itália | D6: =IF(B6<>"",VLOOKUP(B6,'Equipes e Pilotos'!$C$3:$F$30,4,FALSE),"") -> Mercedes | E6: =IF(B6<>"",SUMIF(Resultados!C:C,B6,Resultados!F:F),"") -> 340 | F6: =IF(B6<>"",SUMPRODUCT((Resultados!$B$1:$B$602=1)*(Resultados!$C$1:$C$602=B6)*1),"") -> 9 | G6: =IF(B6<>"",SUMPRODUCT((Resultados!$B$1:$B$602=2)*(Resultados!$C$1:$C$602=B6)*1),"") -> 3 | H6: =IF(B6<>"",SUMPRODUCT((Resultados!$B$1:$B$602=3)*(Resultados!$C$1:$C$602=B6)*1),"") -> 3 | I6: =IF(B6<>"",SUMPRODUCT((Resultados!$B$1:$B$602=4)*(Resultados!$C$1:$C$602=B6)*1),"") -> 1 | J6: =IF(B6<>"",SUMPRODUCT((Resultados!$B$1:$B$602=5)*(Resultados!$C$1:$C$602=B6)*1),"") -> 2 | K6: =IF(B6<>"",SUMPRODUCT((Resultados!$B$1:$B$602=6)*(Resultados!$C$1:$C$602=B6)*1),"") -> 1 | L6: =IF(B6<>"",SUMPRODUCT((Resultados!$B$1:$B$602=7)*(Resultados!$C$1:$C$602=B6)*1),"") -> 0 | M6: =IF(B6<>"",SUMPRODUCT((Resultados!$B$1:$B$602=8)*(Resultados!$C$1:$C$602=B6)*1),"") -> 0 | N6: =IF(B6<>"",SUMPRODUCT((Resultados!$B$1:$B$602=9)*(Resultados!$C$1:$C$602=B6)*1),"") -> 0 | O6: =IF(B6<>"",SUMPRODUCT((Resultados!$B$1:$B$602=10)*(Resultados!$C$1:$C$602=B6)*1),"") -> 0 | P6: =IF(B6<>"",SUMPRODUCT((Resultados!$B$1:$B$602=11)*(Resultados!$C$1:$C$602=B6)*1),"") -> 0 | Q6: =IF(B6<>"",SUMPRODUCT((Resultados!$B$1:$B$602=12)*(Resultados!$C$1:$C$602=B6)*1),"") -> 0 | R6: =IF(B6<>"",SUMPRODUCT((Resultados!$B$1:$B$602=13)*(Resultados!$C$1:$C$602=B6)*1),"") -> 0 | S6: =IF(B6<>"",SUMPRODUCT((Resultados!$B$1:$B$602=14)*(Resultados!$C$1:$C$602=B6)*1),"") -> 0 | T6: =IF(B6<>"",SUMPRODUCT((Resultados!$B$1:$B$602=15)*(Resultados!$C$1:$C$602=B6)*1),"") -> 1 | U6: =IF(B6<>"",SUMPRODUCT((Resultados!$B$1:$B$602=16)*(Resultados!$C$1:$C$602=B6)*1),"") -> 1 | V6: =IF(B6<>"",SUMPRODUCT((Resultados!$B$1:$B$602=17)*(Resultados!$C$1:$C$602=B6)*1),"") -> 0 | W6: =IF(B6<>"",SUMPRODUCT((Resultados!$B$1:$B$602=18)*(Resultados!$C$1:$C$602=B6)*1),"") -> 0 | X6: =IF(B6<>"",SUMPRODUCT((Resultados!$B$1:$B$602=19)*(Resultados!$C$1:$C$602=B6)*1),"") -> 0 | Y6: =IF(B6<>"",SUMPRODUCT((Resultados!$B$1:$B$602=20)*(Resultados!$C$1:$C$602=B6)*1),"") -> 0 | Z6: =IF(B6<>"",SUMPRODUCT((Resultados!$B$1:$B$602=21)*(Resultados!$C$1:$C$602=B6)*1),"") -> 0 | AA6: =IF(B6<>"",SUMPRODUCT((Resultados!$B$1:$B$602=22)*(Resultados!$C$1:$C$602=B6)*1),"") -> 0 | AB6: =IF(B6<>"",SUMPRODUCT((Resultados!$B$1:$B$602=23)*(Resultados!$C$1:$C$602=B6)*1),"") -> 0 | AC6: =IF(B6<>"",SUMPRODUCT((Resultados!$B$1:$B$602=24)*(Resultados!$C$1:$C$602=B6)*1),"") -> 0 | AD6: =IF(B6<>"",SUMPRODUCT(($E$3:$E$30=E6)*($F$3:$F$30>F6)),"") -> 0 | AE6: =IF(B6<>"",SUMPRODUCT(($E$3:$E$30=E6)*($F$3:$F$30=F6)*($G$3:$G$30>G6)),"") -> 0 | AF6: =IF(B6<>"",SUMPRODUCT(($E$3:$E$30=E6)*($F$3:$F$30=F6)*($G$3:$G$30=G6)*($H$3:$H$30>H6)),"") -> 0 | AG6: =IF(B6<>"",SUMPRODUCT(($E$3:$E$30=E6)*($F$3:$F$30=F6)*($G$3:$G$30=G6)*($H$3:$H$30=H6)*($I$3:$I$30>I6)),"") -> 0 | AH6: =IF(B6<>"",SUMPRODUCT(($E$3:$E$30=E6)*($F$3:$F$30=F6)*($G$3:$G$30=G6)*($H$3:$H$30=H6)*($I$3:$I$30=I6)*($J$3:$J$30>J6)),"") -> 0 | AI6: =IF(B6<>"",SUMPRODUCT(($E$3:$E$30=E6)*($F$3:$F$30=F6)*($G$3:$G$30=G6)*($H$3:$H$30=H6)*($I$3:$I$30=I6)*($J$3:$J$30=J6)*($K$3:$K$30>K6)),"") -> 0 | AJ6: =IF(B6<>"",SUMPRODUCT(($E$3:$E$30=E6)*($F$3:$F$30=F6)*($G$3:$G$30=G6)*($H$3:$H$30=H6)*($I$3:$I$30=I6)*($J$3:$J$30=J6)*($K$3:$K$30=K6)*($L$3:$L$30>L6)),"") -> 0 | AK6: =IF(B6<>"",SUMPRODUCT(($E$3:$E$30=E6)*($F$3:$F$30=F6)*($G$3:$G$30=G6)*($H$3:$H$30=H6)*($I$3:$I$30=I6)*($J$3:$J$30=J6)*($K$3:$K$30=K6)*($L$3:$L$30=L6)*($M$3:$M$30>M6)),"") -> 0 | AL6: =IF(B6<>"",SUMPRODUCT(($E$3:$E$30=E6)*($F$3:$F$30=F6)*($G$3:$G$30=G6)*($H$3:$H$30=H6)*($I$3:$I$30=I6)*($J$3:$J$30=J6)*($K$3:$K$30=K6)*($L$3:$L$30=L6)*($M$3:$M$30=M6)*($N$3:$N$30>N6)),"") -> 0 | AM6: =IF(B6<>"",SUMPRODUCT(($E$3:$E$30=E6)*($F$3:$F$30=F6)*($G$3:$G$30=G6)*($H$3:$H$30=H6)*($I$3:$I$30=I6)*($J$3:$J$30=J6)*($K$3:$K$30=K6)*($L$3:$L$30=L6)*($M$3:$M$30=M6)*($N$3:$N$30=N6)*($O$3:$O$30>O6)),"") -> 0 | AN6: =IF(B6<>"",SUMPRODUCT(($E$3:$E$30=E6)*($F$3:$F$30=F6)*($G$3:$G$30=G6)*($H$3:$H$30=H6)*($I$3:$I$30=I6)*($J$3:$J$30=J6)*($K$3:$K$30=K6)*($L$3:$L$30=L6)*($M$3:$M$30=M6)*($N$3:$N$30=N6)*($O$3:$O$30=O6)*($P$3:$P$30>P6)),"") -> 0 | AO6: =IF(B6<>"",SUMPRODUCT(($E$3:$E$30=E6)*($F$3:$F$30=F6)*($G$3:$G$30=G6)*($H$3:$H$30=H6)*($I$3:$I$30=I6)*($J$3:$J$30=J6)*($K$3:$K$30=K6)*($L$3:$L$30=L6)*($M$3:$M$30=M6)*($N$3:$N$30=N6)*($O$3:$O$30=O6)*($P$3:$P$30=P6)*($Q$3:$Q$30>Q6)),"") -> 0 | AP6: =IF(B6<>"",SUMPRODUCT(($E$3:$E$30=E6)*($F$3:$F$30=F6)*($G$3:$G$30=G6)*($H$3:$H$30=H6)*($I$3:$I$30=I6)*($J$3:$J$30=J6)*($K$3:$K$30=K6)*($L$3:$L$30=L6)*($M$3:$M$30=M6)*($N$3:$N$30=N6)*($O$3:$O$30=O6)*($P$3:$P$30=P6)*($Q$3:$Q$30=Q6)*($R$3:$R$30>R6)),"") -> 0 | AQ6: =IF(B6<>"",SUMPRODUCT(($E$3:$E$30=E6)*($F$3:$F$30=F6)*($G$3:$G$30=G6)*($H$3:$H$30=H6)*($I$3:$I$30=I6)*($J$3:$J$30=J6)*($K$3:$K$30=K6)*($L$3:$L$30=L6)*($M$3:$M$30=M6)*($N$3:$N$30=N6)*($O$3:$O$30=O6)*($P$3:$P$30=P6)*($Q$3:$Q$30=Q6)*($R$3:$R$30=R6)*($S$3:$S$30>S6)),"") -> 0 | AR6: =IF(B6<>"",SUMPRODUCT(($E$3:$E$30=E6)*($F$3:$F$30=F6)*($G$3:$G$30=G6)*($H$3:$H$30=H6)*($I$3:$I$30=I6)*($J$3:$J$30=J6)*($K$3:$K$30=K6)*($L$3:$L$30=L6)*($M$3:$M$30=M6)*($N$3:$N$30=N6)*($O$3:$O$30=O6)*($P$3:$P$30=P6)*($Q$3:$Q$30=Q6)*($R$3:$R$30=R6)*($S$3:$S$30=S6)*($T$3:$T$30>T6)),"") -> 0 | AS6: =IF(B6<>"",SUMPRODUCT(($E$3:$E$30=E6)*($F$3:$F$30=F6)*($G$3:$G$30=G6)*($H$3:$H$30=H6)*($I$3:$I$30=I6)*($J$3:$J$30=J6)*($K$3:$K$30=K6)*($L$3:$L$30=L6)*($M$3:$M$30=M6)*($N$3:$N$30=N6)*($O$3:$O$30=O6)*($P$3:$P$30=P6)*($Q$3:$Q$30=Q6)*($R$3:$R$30=R6)*($S$3:$S$30=S6)*($T$3:$T$30=T6)*($U$3:$U$30>U6)),"") -> 0 | AT6: =IF(B6<>"",SUMPRODUCT(($E$3:$E$30=E6)*($F$3:$F$30=F6)*($G$3:$G$30=G6)*($H$3:$H$30=H6)*($I$3:$I$30=I6)*($J$3:$J$30=J6)*($K$3:$K$30=K6)*($L$3:$L$30=L6)*($M$3:$M$30=M6)*($N$3:$N$30=N6)*($O$3:$O$30=O6)*($P$3:$P$30=P6)*($Q$3:$Q$30=Q6)*($R$3:$R$30=R6)*($S$3:$S$30=S6)*($T$3:$T$30=T6)*($U$3:$U$30=U6)*($V$3:$V$30>V6)),"") -> 0 | AU6: =IF(B6<>"",SUMPRODUCT(($E$3:$E$30=E6)*($F$3:$F$30=F6)*($G$3:$G$30=G6)*($H$3:$H$30=H6)*($I$3:$I$30=I6)*($J$3:$J$30=J6)*($K$3:$K$30=K6)*($L$3:$L$30=L6)*($M$3:$M$30=M6)*($N$3:$N$30=N6)*($O$3:$O$30=O6)*($P$3:$P$30=P6)*($Q$3:$Q$30=Q6)*($R$3:$R$30=R6)*($S$3:$S$30=S6)*($T$3:$T$30=T6)*($U$3:$U$30=U6)*($V$3:$V$30=V6)*($W$3:$W$30>W6)),"") -> 0 | AV6: =IF(B6<>"",SUMPRODUCT(($E$3:$E$30=E6)*($F$3:$F$30=F6)*($G$3:$G$30=G6)*($H$3:$H$30=H6)*($I$3:$I$30=I6)*($J$3:$J$30=J6)*($K$3:$K$30=K6)*($L$3:$L$30=L6)*($M$3:$M$30=M6)*($N$3:$N$30=N6)*($O$3:$O$30=O6)*($P$3:$P$30=P6)*($Q$3:$Q$30=Q6)*($R$3:$R$30=R6)*($S$3:$S$30=S6)*($T$3:$T$30=T6)*($U$3:$U$30=U6)*($V$3:$V$30=V6)*($W$3:$W$30=W6)*($X$3:$X$30>X6)),"") -> 0 | AW6: =IF(B6<>"",SUMPRODUCT(($E$3:$E$30=E6)*($F$3:$F$30=F6)*($G$3:$G$30=G6)*($H$3:$H$30=H6)*($I$3:$I$30=I6)*($J$3:$J$30=J6)*($K$3:$K$30=K6)*($L$3:$L$30=L6)*($M$3:$M$30=M6)*($N$3:$N$30=N6)*($O$3:$O$30=O6)*($P$3:$P$30=P6)*($Q$3:$Q$30=Q6)*($R$3:$R$30=R6)*($S$3:$S$30=S6)*($T$3:$T$30=T6)*($U$3:$U$30=U6)*($V$3:$V$30=V6)*($W$3:$W$30=W6)*($X$3:$X$30=X6)*($Y$3:$Y$30>Y6)),"") -> 0 | AX6: =IF(B6<>"",SUMPRODUCT(($E$3:$E$30=E6)*($F$3:$F$30=F6)*($G$3:$G$30=G6)*($H$3:$H$30=H6)*($I$3:$I$30=I6)*($J$3:$J$30=J6)*($K$3:$K$30=K6)*($L$3:$L$30=L6)*($M$3:$M$30=M6)*($N$3:$N$30=N6)*($O$3:$O$30=O6)*($P$3:$P$30=P6)*($Q$3:$Q$30=Q6)*($R$3:$R$30=R6)*($S$3:$S$30=S6)*($T$3:$T$30=T6)*($U$3:$U$30=U6)*($V$3:$V$30=V6)*($W$3:$W$30=W6)*($X$3:$X$30=X6)*($Y$3:$Y$30=Y6)*($Z$3:$Z$30>Z6)),"") -> 0 | AY6: =IF(B6<>"",SUMPRODUCT(($E$3:$E$30=E6)*($F$3:$F$30=F6)*($G$3:$G$30=G6)*($H$3:$H$30=H6)*($I$3:$I$30=I6)*($J$3:$J$30=J6)*($K$3:$K$30=K6)*($L$3:$L$30=L6)*($M$3:$M$30=M6)*($N$3:$N$30=N6)*($O$3:$O$30=O6)*($P$3:$P$30=P6)*($Q$3:$Q$30=Q6)*($R$3:$R$30=R6)*($S$3:$S$30=S6)*($T$3:$T$30=T6)*($U$3:$U$30=U6)*($V$3:$V$30=V6)*($W$3:$W$30=W6)*($X$3:$X$30=X6)*($Y$3:$Y$30=Y6)*($Z$3:$Z$30=Z6)*($AA$3:$AA$30>AA6)),"") -> 0 | AZ6: =IF(B6<>"",SUMPRODUCT(($E$3:$E$30=E6)*($F$3:$F$30=F6)*($G$3:$G$30=G6)*($H$3:$H$30=H6)*($I$3:$I$30=I6)*($J$3:$J$30=J6)*($K$3:$K$30=K6)*($L$3:$L$30=L6)*($M$3:$M$30=M6)*($N$3:$N$30=N6)*($O$3:$O$30=O6)*($P$3:$P$30=P6)*($Q$3:$Q$30=Q6)*($R$3:$R$30=R6)*($S$3:$S$30=S6)*($T$3:$T$30=T6)*($U$3:$U$30=U6)*($V$3:$V$30=V6)*($W$3:$W$30=W6)*($X$3:$X$30=X6)*($Y$3:$Y$30=Y6)*($Z$3:$Z$30=Z6)*($AA$3:$AA$30=AA6)*($AB$3:$AB$30>AB6)),"") -> 0 | BA6: =IF(B6<>"",SUMPRODUCT(($E$3:$E$30=E6)*($F$3:$F$30=F6)*($G$3:$G$30=G6)*($H$3:$H$30=H6)*($I$3:$I$30=I6)*($J$3:$J$30=J6)*($K$3:$K$30=K6)*($L$3:$L$30=L6)*($M$3:$M$30=M6)*($N$3:$N$30=N6)*($O$3:$O$30=O6)*($P$3:$P$30=P6)*($Q$3:$Q$30=Q6)*($R$3:$R$30=R6)*($S$3:$S$30=S6)*($T$3:$T$30=T6)*($U$3:$U$30=U6)*($V$3:$V$30=V6)*($W$3:$W$30=W6)*($X$3:$X$30=X6)*($Y$3:$Y$30=Y6)*($Z$3:$Z$30=Z6)*($AA$3:$AA$30=AA6)*($AB$3:$AB$30=AB6)*($AC$3:$AC$30>AC6)),"") -> 0 | BB6: =IF(B6<>"",SUMPRODUCT(($E$3:$E$30=E6)*($F$3:$F$30=F6)*($G$3:$G$30=G6)*($H$3:$H$30=H6)*($I$3:$I$30=I6)*($J$3:$J$30=J6)*($K$3:$K$30=K6)*($L$3:$L$30=L6)*($M$3:$M$30=M6)*($N$3:$N$30=N6)*($O$3:$O$30=O6)*($P$3:$P$30=P6)*($Q$3:$Q$30=Q6)*($R$3:$R$30=R6)*($S$3:$S$30=S6)*($T$3:$T$30=T6)*($U$3:$U$30=U6)*($V$3:$V$30=V6)*($W$3:$W$30=W6)*($X$3:$X$30=X6)*($Y$3:$Y$30=Y6)*($Z$3:$Z$30=Z6)*($AA$3:$AA$30=AA6)*($AB$3:$AB$30=AB6)*($AC$3:$AC$30=AC6)*($BC$3:$BC$30<BC6)),"") -> 0 | BC6: =IF(B6<>"",'Equipes e Pilotos'!B6,"") -> 4
A7: =IF(B7<>"",RANK(E7,E$3:E$30)+SUM(AD7:BB7),"") -> 4 | B7: =IF('Equipes e Pilotos'!C7<>"",'Equipes e Pilotos'!C7,"") -> Max Verstappen | C7: =IF(B7<>"",VLOOKUP(B7,'Equipes e Pilotos'!$C$3:$F$30,3,FALSE),"") -> Holanda | D7: =IF(B7<>"",VLOOKUP(B7,'Equipes e Pilotos'!$C$3:$F$30,4,FALSE),"") -> Red Bull | E7: =IF(B7<>"",SUMIF(Resultados!C:C,B7,Resultados!F:F),"") -> 221 | F7: =IF(B7<>"",SUMPRODUCT((Resultados!$B$1:$B$602=1)*(Resultados!$C$1:$C$602=B7)*1),"") -> 1 | G7: =IF(B7<>"",SUMPRODUCT((Resultados!$B$1:$B$602=2)*(Resultados!$C$1:$C$602=B7)*1),"") -> 4 | H7: =IF(B7<>"",SUMPRODUCT((Resultados!$B$1:$B$602=3)*(Resultados!$C$1:$C$602=B7)*1),"") -> 3 | I7: =IF(B7<>"",SUMPRODUCT((Resultados!$B$1:$B$602=4)*(Resultados!$C$1:$C$602=B7)*1),"") -> 1 | J7: =IF(B7<>"",SUMPRODUCT((Resultados!$B$1:$B$602=5)*(Resultados!$C$1:$C$602=B7)*1),"") -> 2 | K7: =IF(B7<>"",SUMPRODUCT((Resultados!$B$1:$B$602=6)*(Resultados!$C$1:$C$602=B7)*1),"") -> 3 | L7: =IF(B7<>"",SUMPRODUCT((Resultados!$B$1:$B$602=7)*(Resultados!$C$1:$C$602=B7)*1),"") -> 1 | M7: =IF(B7<>"",SUMPRODUCT((Resultados!$B$1:$B$602=8)*(Resultados!$C$1:$C$602=B7)*1),"") -> 1 | N7: =IF(B7<>"",SUMPRODUCT((Resultados!$B$1:$B$602=9)*(Resultados!$C$1:$C$602=B7)*1),"") -> 1 | O7: =IF(B7<>"",SUMPRODUCT((Resultados!$B$1:$B$602=10)*(Resultados!$C$1:$C$602=B7)*1),"") -> 0 | P7: =IF(B7<>"",SUMPRODUCT((Resultados!$B$1:$B$602=11)*(Resultados!$C$1:$C$602=B7)*1),"") -> 0 | Q7: =IF(B7<>"",SUMPRODUCT((Resultados!$B$1:$B$602=12)*(Resultados!$C$1:$C$602=B7)*1),"") -> 0 | R7: =IF(B7<>"",SUMPRODUCT((Resultados!$B$1:$B$602=13)*(Resultados!$C$1:$C$602=B7)*1),"") -> 0 | S7: =IF(B7<>"",SUMPRODUCT((Resultados!$B$1:$B$602=14)*(Resultados!$C$1:$C$602=B7)*1),"") -> 0 | T7: =IF(B7<>"",SUMPRODUCT((Resultados!$B$1:$B$602=15)*(Resultados!$C$1:$C$602=B7)*1),"") -> 0 | U7: =IF(B7<>"",SUMPRODUCT((Resultados!$B$1:$B$602=16)*(Resultados!$C$1:$C$602=B7)*1),"") -> 1 | V7: =IF(B7<>"",SUMPRODUCT((Resultados!$B$1:$B$602=17)*(Resultados!$C$1:$C$602=B7)*1),"") -> 0 | W7: =IF(B7<>"",SUMPRODUCT((Resultados!$B$1:$B$602=18)*(Resultados!$C$1:$C$602=B7)*1),"") -> 0 | X7: =IF(B7<>"",SUMPRODUCT((Resultados!$B$1:$B$602=19)*(Resultados!$C$1:$C$602=B7)*1),"") -> 0 | Y7: =IF(B7<>"",SUMPRODUCT((Resultados!$B$1:$B$602=20)*(Resultados!$C$1:$C$602=B7)*1),"") -> 1 | Z7: =IF(B7<>"",SUMPRODUCT((Resultados!$B$1:$B$602=21)*(Resultados!$C$1:$C$602=B7)*1),"") -> 0 | AA7: =IF(B7<>"",SUMPRODUCT((Resultados!$B$1:$B$602=22)*(Resultados!$C$1:$C$602=B7)*1),"") -> 2 | AB7: =IF(B7<>"",SUMPRODUCT((Resultados!$B$1:$B$602=23)*(Resultados!$C$1:$C$602=B7)*1),"") -> 0 | AC7: =IF(B7<>"",SUMPRODUCT((Resultados!$B$1:$B$602=24)*(Resultados!$C$1:$C$602=B7)*1),"") -> 0 | AD7: =IF(B7<>"",SUMPRODUCT(($E$3:$E$30=E7)*($F$3:$F$30>F7)),"") -> 0 | AE7: =IF(B7<>"",SUMPRODUCT(($E$3:$E$30=E7)*($F$3:$F$30=F7)*($G$3:$G$30>G7)),"") -> 0 | AF7: =IF(B7<>"",SUMPRODUCT(($E$3:$E$30=E7)*($F$3:$F$30=F7)*($G$3:$G$30=G7)*($H$3:$H$30>H7)),"") -> 0 | AG7: =IF(B7<>"",SUMPRODUCT(($E$3:$E$30=E7)*($F$3:$F$30=F7)*($G$3:$G$30=G7)*($H$3:$H$30=H7)*($I$3:$I$30>I7)),"") -> 0 | AH7: =IF(B7<>"",SUMPRODUCT(($E$3:$E$30=E7)*($F$3:$F$30=F7)*($G$3:$G$30=G7)*($H$3:$H$30=H7)*($I$3:$I$30=I7)*($J$3:$J$30>J7)),"") -> 0 | AI7: =IF(B7<>"",SUMPRODUCT(($E$3:$E$30=E7)*($F$3:$F$30=F7)*($G$3:$G$30=G7)*($H$3:$H$30=H7)*($I$3:$I$30=I7)*($J$3:$J$30=J7)*($K$3:$K$30>K7)),"") -> 0 | AJ7: =IF(B7<>"",SUMPRODUCT(($E$3:$E$30=E7)*($F$3:$F$30=F7)*($G$3:$G$30=G7)*($H$3:$H$30=H7)*($I$3:$I$30=I7)*($J$3:$J$30=J7)*($K$3:$K$30=K7)*($L$3:$L$30>L7)),"") -> 0 | AK7: =IF(B7<>"",SUMPRODUCT(($E$3:$E$30=E7)*($F$3:$F$30=F7)*($G$3:$G$30=G7)*($H$3:$H$30=H7)*($I$3:$I$30=I7)*($J$3:$J$30=J7)*($K$3:$K$30=K7)*($L$3:$L$30=L7)*($M$3:$M$30>M7)),"") -> 0 | AL7: =IF(B7<>"",SUMPRODUCT(($E$3:$E$30=E7)*($F$3:$F$30=F7)*($G$3:$G$30=G7)*($H$3:$H$30=H7)*($I$3:$I$30=I7)*($J$3:$J$30=J7)*($K$3:$K$30=K7)*($L$3:$L$30=L7)*($M$3:$M$30=M7)*($N$3:$N$30>N7)),"") -> 0 | AM7: =IF(B7<>"",SUMPRODUCT(($E$3:$E$30=E7)*($F$3:$F$30=F7)*($G$3:$G$30=G7)*($H$3:$H$30=H7)*($I$3:$I$30=I7)*($J$3:$J$30=J7)*($K$3:$K$30=K7)*($L$3:$L$30=L7)*($M$3:$M$30=M7)*($N$3:$N$30=N7)*($O$3:$O$30>O7)),"") -> 0 | AN7: =IF(B7<>"",SUMPRODUCT(($E$3:$E$30=E7)*($F$3:$F$30=F7)*($G$3:$G$30=G7)*($H$3:$H$30=H7)*($I$3:$I$30=I7)*($J$3:$J$30=J7)*($K$3:$K$30=K7)*($L$3:$L$30=L7)*($M$3:$M$30=M7)*($N$3:$N$30=N7)*($O$3:$O$30=O7)*($P$3:$P$30>P7)),"") -> 0 | AO7: =IF(B7<>"",SUMPRODUCT(($E$3:$E$30=E7)*($F$3:$F$30=F7)*($G$3:$G$30=G7)*($H$3:$H$30=H7)*($I$3:$I$30=I7)*($J$3:$J$30=J7)*($K$3:$K$30=K7)*($L$3:$L$30=L7)*($M$3:$M$30=M7)*($N$3:$N$30=N7)*($O$3:$O$30=O7)*($P$3:$P$30=P7)*($Q$3:$Q$30>Q7)),"") -> 0 | AP7: =IF(B7<>"",SUMPRODUCT(($E$3:$E$30=E7)*($F$3:$F$30=F7)*($G$3:$G$30=G7)*($H$3:$H$30=H7)*($I$3:$I$30=I7)*($J$3:$J$30=J7)*($K$3:$K$30=K7)*($L$3:$L$30=L7)*($M$3:$M$30=M7)*($N$3:$N$30=N7)*($O$3:$O$30=O7)*($P$3:$P$30=P7)*($Q$3:$Q$30=Q7)*($R$3:$R$30>R7)),"") -> 0 | AQ7: =IF(B7<>"",SUMPRODUCT(($E$3:$E$30=E7)*($F$3:$F$30=F7)*($G$3:$G$30=G7)*($H$3:$H$30=H7)*($I$3:$I$30=I7)*($J$3:$J$30=J7)*($K$3:$K$30=K7)*($L$3:$L$30=L7)*($M$3:$M$30=M7)*($N$3:$N$30=N7)*($O$3:$O$30=O7)*($P$3:$P$30=P7)*($Q$3:$Q$30=Q7)*($R$3:$R$30=R7)*($S$3:$S$30>S7)),"") -> 0 | AR7: =IF(B7<>"",SUMPRODUCT(($E$3:$E$30=E7)*($F$3:$F$30=F7)*($G$3:$G$30=G7)*($H$3:$H$30=H7)*($I$3:$I$30=I7)*($J$3:$J$30=J7)*($K$3:$K$30=K7)*($L$3:$L$30=L7)*($M$3:$M$30=M7)*($N$3:$N$30=N7)*($O$3:$O$30=O7)*($P$3:$P$30=P7)*($Q$3:$Q$30=Q7)*($R$3:$R$30=R7)*($S$3:$S$30=S7)*($T$3:$T$30>T7)),"") -> 0 | AS7: =IF(B7<>"",SUMPRODUCT(($E$3:$E$30=E7)*($F$3:$F$30=F7)*($G$3:$G$30=G7)*($H$3:$H$30=H7)*($I$3:$I$30=I7)*($J$3:$J$30=J7)*($K$3:$K$30=K7)*($L$3:$L$30=L7)*($M$3:$M$30=M7)*($N$3:$N$30=N7)*($O$3:$O$30=O7)*($P$3:$P$30=P7)*($Q$3:$Q$30=Q7)*($R$3:$R$30=R7)*($S$3:$S$30=S7)*($T$3:$T$30=T7)*($U$3:$U$30>U7)),"") -> 0 | AT7: =IF(B7<>"",SUMPRODUCT(($E$3:$E$30=E7)*($F$3:$F$30=F7)*($G$3:$G$30=G7)*($H$3:$H$30=H7)*($I$3:$I$30=I7)*($J$3:$J$30=J7)*($K$3:$K$30=K7)*($L$3:$L$30=L7)*($M$3:$M$30=M7)*($N$3:$N$30=N7)*($O$3:$O$30=O7)*($P$3:$P$30=P7)*($Q$3:$Q$30=Q7)*($R$3:$R$30=R7)*($S$3:$S$30=S7)*($T$3:$T$30=T7)*($U$3:$U$30=U7)*($V$3:$V$30>V7)),"") -> 0 | AU7: =IF(B7<>"",SUMPRODUCT(($E$3:$E$30=E7)*($F$3:$F$30=F7)*($G$3:$G$30=G7)*($H$3:$H$30=H7)*($I$3:$I$30=I7)*($J$3:$J$30=J7)*($K$3:$K$30=K7)*($L$3:$L$30=L7)*($M$3:$M$30=M7)*($N$3:$N$30=N7)*($O$3:$O$30=O7)*($P$3:$P$30=P7)*($Q$3:$Q$30=Q7)*($R$3:$R$30=R7)*($S$3:$S$30=S7)*($T$3:$T$30=T7)*($U$3:$U$30=U7)*($V$3:$V$30=V7)*($W$3:$W$30>W7)),"") -> 0 | AV7: =IF(B7<>"",SUMPRODUCT(($E$3:$E$30=E7)*($F$3:$F$30=F7)*($G$3:$G$30=G7)*($H$3:$H$30=H7)*($I$3:$I$30=I7)*($J$3:$J$30=J7)*($K$3:$K$30=K7)*($L$3:$L$30=L7)*($M$3:$M$30=M7)*($N$3:$N$30=N7)*($O$3:$O$30=O7)*($P$3:$P$30=P7)*($Q$3:$Q$30=Q7)*($R$3:$R$30=R7)*($S$3:$S$30=S7)*($T$3:$T$30=T7)*($U$3:$U$30=U7)*($V$3:$V$30=V7)*($W$3:$W$30=W7)*($X$3:$X$30>X7)),"") -> 0 | AW7: =IF(B7<>"",SUMPRODUCT(($E$3:$E$30=E7)*($F$3:$F$30=F7)*($G$3:$G$30=G7)*($H$3:$H$30=H7)*($I$3:$I$30=I7)*($J$3:$J$30=J7)*($K$3:$K$30=K7)*($L$3:$L$30=L7)*($M$3:$M$30=M7)*($N$3:$N$30=N7)*($O$3:$O$30=O7)*($P$3:$P$30=P7)*($Q$3:$Q$30=Q7)*($R$3:$R$30=R7)*($S$3:$S$30=S7)*($T$3:$T$30=T7)*($U$3:$U$30=U7)*($V$3:$V$30=V7)*($W$3:$W$30=W7)*($X$3:$X$30=X7)*($Y$3:$Y$30>Y7)),"") -> 0 | AX7: =IF(B7<>"",SUMPRODUCT(($E$3:$E$30=E7)*($F$3:$F$30=F7)*($G$3:$G$30=G7)*($H$3:$H$30=H7)*($I$3:$I$30=I7)*($J$3:$J$30=J7)*($K$3:$K$30=K7)*($L$3:$L$30=L7)*($M$3:$M$30=M7)*($N$3:$N$30=N7)*($O$3:$O$30=O7)*($P$3:$P$30=P7)*($Q$3:$Q$30=Q7)*($R$3:$R$30=R7)*($S$3:$S$30=S7)*($T$3:$T$30=T7)*($U$3:$U$30=U7)*($V$3:$V$30=V7)*($W$3:$W$30=W7)*($X$3:$X$30=X7)*($Y$3:$Y$30=Y7)*($Z$3:$Z$30>Z7)),"") -> 0 | AY7: =IF(B7<>"",SUMPRODUCT(($E$3:$E$30=E7)*($F$3:$F$30=F7)*($G$3:$G$30=G7)*($H$3:$H$30=H7)*($I$3:$I$30=I7)*($J$3:$J$30=J7)*($K$3:$K$30=K7)*($L$3:$L$30=L7)*($M$3:$M$30=M7)*($N$3:$N$30=N7)*($O$3:$O$30=O7)*($P$3:$P$30=P7)*($Q$3:$Q$30=Q7)*($R$3:$R$30=R7)*($S$3:$S$30=S7)*($T$3:$T$30=T7)*($U$3:$U$30=U7)*($V$3:$V$30=V7)*($W$3:$W$30=W7)*($X$3:$X$30=X7)*($Y$3:$Y$30=Y7)*($Z$3:$Z$30=Z7)*($AA$3:$AA$30>AA7)),"") -> 0 | AZ7: =IF(B7<>"",SUMPRODUCT(($E$3:$E$30=E7)*($F$3:$F$30=F7)*($G$3:$G$30=G7)*($H$3:$H$30=H7)*($I$3:$I$30=I7)*($J$3:$J$30=J7)*($K$3:$K$30=K7)*($L$3:$L$30=L7)*($M$3:$M$30=M7)*($N$3:$N$30=N7)*($O$3:$O$30=O7)*($P$3:$P$30=P7)*($Q$3:$Q$30=Q7)*($R$3:$R$30=R7)*($S$3:$S$30=S7)*($T$3:$T$30=T7)*($U$3:$U$30=U7)*($V$3:$V$30=V7)*($W$3:$W$30=W7)*($X$3:$X$30=X7)*($Y$3:$Y$30=Y7)*($Z$3:$Z$30=Z7)*($AA$3:$AA$30=AA7)*($AB$3:$AB$30>AB7)),"") -> 0 | BA7: =IF(B7<>"",SUMPRODUCT(($E$3:$E$30=E7)*($F$3:$F$30=F7)*($G$3:$G$30=G7)*($H$3:$H$30=H7)*($I$3:$I$30=I7)*($J$3:$J$30=J7)*($K$3:$K$30=K7)*($L$3:$L$30=L7)*($M$3:$M$30=M7)*($N$3:$N$30=N7)*($O$3:$O$30=O7)*($P$3:$P$30=P7)*($Q$3:$Q$30=Q7)*($R$3:$R$30=R7)*($S$3:$S$30=S7)*($T$3:$T$30=T7)*($U$3:$U$30=U7)*($V$3:$V$30=V7)*($W$3:$W$30=W7)*($X$3:$X$30=X7)*($Y$3:$Y$30=Y7)*($Z$3:$Z$30=Z7)*($AA$3:$AA$30=AA7)*($AB$3:$AB$30=AB7)*($AC$3:$AC$30>AC7)),"") -> 0 | BB7: =IF(B7<>"",SUMPRODUCT(($E$3:$E$30=E7)*($F$3:$F$30=F7)*($G$3:$G$30=G7)*($H$3:$H$30=H7)*($I$3:$I$30=I7)*($J$3:$J$30=J7)*($K$3:$K$30=K7)*($L$3:$L$30=L7)*($M$3:$M$30=M7)*($N$3:$N$30=N7)*($O$3:$O$30=O7)*($P$3:$P$30=P7)*($Q$3:$Q$30=Q7)*($R$3:$R$30=R7)*($S$3:$S$30=S7)*($T$3:$T$30=T7)*($U$3:$U$30=U7)*($V$3:$V$30=V7)*($W$3:$W$30=W7)*($X$3:$X$30=X7)*($Y$3:$Y$30=Y7)*($Z$3:$Z$30=Z7)*($AA$3:$AA$30=AA7)*($AB$3:$AB$30=AB7)*($AC$3:$AC$30=AC7)*($BC$3:$BC$30<BC7)),"") -> 0 | BC7: =IF(B7<>"",'Equipes e Pilotos'!B7,"") -> 5
A8: =IF(B8<>"",RANK(E8,E$3:E$30)+SUM(AD8:BB8),"") -> 8 | B8: =IF('Equipes e Pilotos'!C8<>"",'Equipes e Pilotos'!C8,"") -> Isack Hadjar | C8: =IF(B8<>"",VLOOKUP(B8,'Equipes e Pilotos'!$C$3:$F$30,3,FALSE),"") -> França | D8: =IF(B8<>"",VLOOKUP(B8,'Equipes e Pilotos'!$C$3:$F$30,4,FALSE),"") -> Red Bull | E8: =IF(B8<>"",SUMIF(Resultados!C:C,B8,Resultados!F:F),"") -> 97 | F8: =IF(B8<>"",SUMPRODUCT((Resultados!$B$1:$B$602=1)*(Resultados!$C$1:$C$602=B8)*1),"") -> 0 | G8: =IF(B8<>"",SUMPRODUCT((Resultados!$B$1:$B$602=2)*(Resultados!$C$1:$C$602=B8)*1),"") -> 0 | H8: =IF(B8<>"",SUMPRODUCT((Resultados!$B$1:$B$602=3)*(Resultados!$C$1:$C$602=B8)*1),"") -> 2 | I8: =IF(B8<>"",SUMPRODUCT((Resultados!$B$1:$B$602=4)*(Resultados!$C$1:$C$602=B8)*1),"") -> 0 | J8: =IF(B8<>"",SUMPRODUCT((Resultados!$B$1:$B$602=5)*(Resultados!$C$1:$C$602=B8)*1),"") -> 3 | K8: =IF(B8<>"",SUMPRODUCT((Resultados!$B$1:$B$602=6)*(Resultados!$C$1:$C$602=B8)*1),"") -> 4 | L8: =IF(B8<>"",SUMPRODUCT((Resultados!$B$1:$B$602=7)*(Resultados!$C$1:$C$602=B8)*1),"") -> 0 | M8: =IF(B8<>"",SUMPRODUCT((Resultados!$B$1:$B$602=8)*(Resultados!$C$1:$C$602=B8)*1),"") -> 1 | N8: =IF(B8<>"",SUMPRODUCT((Resultados!$B$1:$B$602=9)*(Resultados!$C$1:$C$602=B8)*1),"") -> 2 | O8: =IF(B8<>"",SUMPRODUCT((Resultados!$B$1:$B$602=10)*(Resultados!$C$1:$C$602=B8)*1),"") -> 0 | P8: =IF(B8<>"",SUMPRODUCT((Resultados!$B$1:$B$602=11)*(Resultados!$C$1:$C$602=B8)*1),"") -> 0 | Q8: =IF(B8<>"",SUMPRODUCT((Resultados!$B$1:$B$602=12)*(Resultados!$C$1:$C$602=B8)*1),"") -> 1 | R8: =IF(B8<>"",SUMPRODUCT((Resultados!$B$1:$B$602=13)*(Resultados!$C$1:$C$602=B8)*1),"") -> 0 | S8: =IF(B8<>"",SUMPRODUCT((Resultados!$B$1:$B$602=14)*(Resultados!$C$1:$C$602=B8)*1),"") -> 0 | T8: =IF(B8<>"",SUMPRODUCT((Resultados!$B$1:$B$602=15)*(Resultados!$C$1:$C$602=B8)*1),"") -> 1 | U8: =IF(B8<>"",SUMPRODUCT((Resultados!$B$1:$B$602=16)*(Resultados!$C$1:$C$602=B8)*1),"") -> 0 | V8: =IF(B8<>"",SUMPRODUCT((Resultados!$B$1:$B$602=17)*(Resultados!$C$1:$C$602=B8)*1),"") -> 0 | W8: =IF(B8<>"",SUMPRODUCT((Resultados!$B$1:$B$602=18)*(Resultados!$C$1:$C$602=B8)*1),"") -> 0 | X8: =IF(B8<>"",SUMPRODUCT((Resultados!$B$1:$B$602=19)*(Resultados!$C$1:$C$602=B8)*1),"") -> 0 | Y8: =IF(B8<>"",SUMPRODUCT((Resultados!$B$1:$B$602=20)*(Resultados!$C$1:$C$602=B8)*1),"") -> 1 | Z8: =IF(B8<>"",SUMPRODUCT((Resultados!$B$1:$B$602=21)*(Resultados!$C$1:$C$602=B8)*1),"") -> 1 | AA8: =IF(B8<>"",SUMPRODUCT((Resultados!$B$1:$B$602=22)*(Resultados!$C$1:$C$602=B8)*1),"") -> 1 | AB8: =IF(B8<>"",SUMPRODUCT((Resultados!$B$1:$B$602=23)*(Resultados!$C$1:$C$602=B8)*1),"") -> 0 | AC8: =IF(B8<>"",SUMPRODUCT((Resultados!$B$1:$B$602=24)*(Resultados!$C$1:$C$602=B8)*1),"") -> 0 | AD8: =IF(B8<>"",SUMPRODUCT(($E$3:$E$30=E8)*($F$3:$F$30>F8)),"") -> 0 | AE8: =IF(B8<>"",SUMPRODUCT(($E$3:$E$30=E8)*($F$3:$F$30=F8)*($G$3:$G$30>G8)),"") -> 0 | AF8: =IF(B8<>"",SUMPRODUCT(($E$3:$E$30=E8)*($F$3:$F$30=F8)*($G$3:$G$30=G8)*($H$3:$H$30>H8)),"") -> 0 | AG8: =IF(B8<>"",SUMPRODUCT(($E$3:$E$30=E8)*($F$3:$F$30=F8)*($G$3:$G$30=G8)*($H$3:$H$30=H8)*($I$3:$I$30>I8)),"") -> 0 | AH8: =IF(B8<>"",SUMPRODUCT(($E$3:$E$30=E8)*($F$3:$F$30=F8)*($G$3:$G$30=G8)*($H$3:$H$30=H8)*($I$3:$I$30=I8)*($J$3:$J$30>J8)),"") -> 0 | AI8: =IF(B8<>"",SUMPRODUCT(($E$3:$E$30=E8)*($F$3:$F$30=F8)*($G$3:$G$30=G8)*($H$3:$H$30=H8)*($I$3:$I$30=I8)*($J$3:$J$30=J8)*($K$3:$K$30>K8)),"") -> 0 | AJ8: =IF(B8<>"",SUMPRODUCT(($E$3:$E$30=E8)*($F$3:$F$30=F8)*($G$3:$G$30=G8)*($H$3:$H$30=H8)*($I$3:$I$30=I8)*($J$3:$J$30=J8)*($K$3:$K$30=K8)*($L$3:$L$30>L8)),"") -> 0 | AK8: =IF(B8<>"",SUMPRODUCT(($E$3:$E$30=E8)*($F$3:$F$30=F8)*($G$3:$G$30=G8)*($H$3:$H$30=H8)*($I$3:$I$30=I8)*($J$3:$J$30=J8)*($K$3:$K$30=K8)*($L$3:$L$30=L8)*($M$3:$M$30>M8)),"") -> 0 | AL8: =IF(B8<>"",SUMPRODUCT(($E$3:$E$30=E8)*($F$3:$F$30=F8)*($G$3:$G$30=G8)*($H$3:$H$30=H8)*($I$3:$I$30=I8)*($J$3:$J$30=J8)*($K$3:$K$30=K8)*($L$3:$L$30=L8)*($M$3:$M$30=M8)*($N$3:$N$30>N8)),"") -> 0 | AM8: =IF(B8<>"",SUMPRODUCT(($E$3:$E$30=E8)*($F$3:$F$30=F8)*($G$3:$G$30=G8)*($H$3:$H$30=H8)*($I$3:$I$30=I8)*($J$3:$J$30=J8)*($K$3:$K$30=K8)*($L$3:$L$30=L8)*($M$3:$M$30=M8)*($N$3:$N$30=N8)*($O$3:$O$30>O8)),"") -> 0 | AN8: =IF(B8<>"",SUMPRODUCT(($E$3:$E$30=E8)*($F$3:$F$30=F8)*($G$3:$G$30=G8)*($H$3:$H$30=H8)*($I$3:$I$30=I8)*($J$3:$J$30=J8)*($K$3:$K$30=K8)*($L$3:$L$30=L8)*($M$3:$M$30=M8)*($N$3:$N$30=N8)*($O$3:$O$30=O8)*($P$3:$P$30>P8)),"") -> 0 | AO8: =IF(B8<>"",SUMPRODUCT(($E$3:$E$30=E8)*($F$3:$F$30=F8)*($G$3:$G$30=G8)*($H$3:$H$30=H8)*($I$3:$I$30=I8)*($J$3:$J$30=J8)*($K$3:$K$30=K8)*($L$3:$L$30=L8)*($M$3:$M$30=M8)*($N$3:$N$30=N8)*($O$3:$O$30=O8)*($P$3:$P$30=P8)*($Q$3:$Q$30>Q8)),"") -> 0 | AP8: =IF(B8<>"",SUMPRODUCT(($E$3:$E$30=E8)*($F$3:$F$30=F8)*($G$3:$G$30=G8)*($H$3:$H$30=H8)*($I$3:$I$30=I8)*($J$3:$J$30=J8)*($K$3:$K$30=K8)*($L$3:$L$30=L8)*($M$3:$M$30=M8)*($N$3:$N$30=N8)*($O$3:$O$30=O8)*($P$3:$P$30=P8)*($Q$3:$Q$30=Q8)*($R$3:$R$30>R8)),"") -> 0 | AQ8: =IF(B8<>"",SUMPRODUCT(($E$3:$E$30=E8)*($F$3:$F$30=F8)*($G$3:$G$30=G8)*($H$3:$H$30=H8)*($I$3:$I$30=I8)*($J$3:$J$30=J8)*($K$3:$K$30=K8)*($L$3:$L$30=L8)*($M$3:$M$30=M8)*($N$3:$N$30=N8)*($O$3:$O$30=O8)*($P$3:$P$30=P8)*($Q$3:$Q$30=Q8)*($R$3:$R$30=R8)*($S$3:$S$30>S8)),"") -> 0 | AR8: =IF(B8<>"",SUMPRODUCT(($E$3:$E$30=E8)*($F$3:$F$30=F8)*($G$3:$G$30=G8)*($H$3:$H$30=H8)*($I$3:$I$30=I8)*($J$3:$J$30=J8)*($K$3:$K$30=K8)*($L$3:$L$30=L8)*($M$3:$M$30=M8)*($N$3:$N$30=N8)*($O$3:$O$30=O8)*($P$3:$P$30=P8)*($Q$3:$Q$30=Q8)*($R$3:$R$30=R8)*($S$3:$S$30=S8)*($T$3:$T$30>T8)),"") -> 0 | AS8: =IF(B8<>"",SUMPRODUCT(($E$3:$E$30=E8)*($F$3:$F$30=F8)*($G$3:$G$30=G8)*($H$3:$H$30=H8)*($I$3:$I$30=I8)*($J$3:$J$30=J8)*($K$3:$K$30=K8)*($L$3:$L$30=L8)*($M$3:$M$30=M8)*($N$3:$N$30=N8)*($O$3:$O$30=O8)*($P$3:$P$30=P8)*($Q$3:$Q$30=Q8)*($R$3:$R$30=R8)*($S$3:$S$30=S8)*($T$3:$T$30=T8)*($U$3:$U$30>U8)),"") -> 0 | AT8: =IF(B8<>"",SUMPRODUCT(($E$3:$E$30=E8)*($F$3:$F$30=F8)*($G$3:$G$30=G8)*($H$3:$H$30=H8)*($I$3:$I$30=I8)*($J$3:$J$30=J8)*($K$3:$K$30=K8)*($L$3:$L$30=L8)*($M$3:$M$30=M8)*($N$3:$N$30=N8)*($O$3:$O$30=O8)*($P$3:$P$30=P8)*($Q$3:$Q$30=Q8)*($R$3:$R$30=R8)*($S$3:$S$30=S8)*($T$3:$T$30=T8)*($U$3:$U$30=U8)*($V$3:$V$30>V8)),"") -> 0 | AU8: =IF(B8<>"",SUMPRODUCT(($E$3:$E$30=E8)*($F$3:$F$30=F8)*($G$3:$G$30=G8)*($H$3:$H$30=H8)*($I$3:$I$30=I8)*($J$3:$J$30=J8)*($K$3:$K$30=K8)*($L$3:$L$30=L8)*($M$3:$M$30=M8)*($N$3:$N$30=N8)*($O$3:$O$30=O8)*($P$3:$P$30=P8)*($Q$3:$Q$30=Q8)*($R$3:$R$30=R8)*($S$3:$S$30=S8)*($T$3:$T$30=T8)*($U$3:$U$30=U8)*($V$3:$V$30=V8)*($W$3:$W$30>W8)),"") -> 0 | AV8: =IF(B8<>"",SUMPRODUCT(($E$3:$E$30=E8)*($F$3:$F$30=F8)*($G$3:$G$30=G8)*($H$3:$H$30=H8)*($I$3:$I$30=I8)*($J$3:$J$30=J8)*($K$3:$K$30=K8)*($L$3:$L$30=L8)*($M$3:$M$30=M8)*($N$3:$N$30=N8)*($O$3:$O$30=O8)*($P$3:$P$30=P8)*($Q$3:$Q$30=Q8)*($R$3:$R$30=R8)*($S$3:$S$30=S8)*($T$3:$T$30=T8)*($U$3:$U$30=U8)*($V$3:$V$30=V8)*($W$3:$W$30=W8)*($X$3:$X$30>X8)),"") -> 0 | AW8: =IF(B8<>"",SUMPRODUCT(($E$3:$E$30=E8)*($F$3:$F$30=F8)*($G$3:$G$30=G8)*($H$3:$H$30=H8)*($I$3:$I$30=I8)*($J$3:$J$30=J8)*($K$3:$K$30=K8)*($L$3:$L$30=L8)*($M$3:$M$30=M8)*($N$3:$N$30=N8)*($O$3:$O$30=O8)*($P$3:$P$30=P8)*($Q$3:$Q$30=Q8)*($R$3:$R$30=R8)*($S$3:$S$30=S8)*($T$3:$T$30=T8)*($U$3:$U$30=U8)*($V$3:$V$30=V8)*($W$3:$W$30=W8)*($X$3:$X$30=X8)*($Y$3:$Y$30>Y8)),"") -> 0 | AX8: =IF(B8<>"",SUMPRODUCT(($E$3:$E$30=E8)*($F$3:$F$30=F8)*($G$3:$G$30=G8)*($H$3:$H$30=H8)*($I$3:$I$30=I8)*($J$3:$J$30=J8)*($K$3:$K$30=K8)*($L$3:$L$30=L8)*($M$3:$M$30=M8)*($N$3:$N$30=N8)*($O$3:$O$30=O8)*($P$3:$P$30=P8)*($Q$3:$Q$30=Q8)*($R$3:$R$30=R8)*($S$3:$S$30=S8)*($T$3:$T$30=T8)*($U$3:$U$30=U8)*($V$3:$V$30=V8)*($W$3:$W$30=W8)*($X$3:$X$30=X8)*($Y$3:$Y$30=Y8)*($Z$3:$Z$30>Z8)),"") -> 0 | AY8: =IF(B8<>"",SUMPRODUCT(($E$3:$E$30=E8)*($F$3:$F$30=F8)*($G$3:$G$30=G8)*($H$3:$H$30=H8)*($I$3:$I$30=I8)*($J$3:$J$30=J8)*($K$3:$K$30=K8)*($L$3:$L$30=L8)*($M$3:$M$30=M8)*($N$3:$N$30=N8)*($O$3:$O$30=O8)*($P$3:$P$30=P8)*($Q$3:$Q$30=Q8)*($R$3:$R$30=R8)*($S$3:$S$30=S8)*($T$3:$T$30=T8)*($U$3:$U$30=U8)*($V$3:$V$30=V8)*($W$3:$W$30=W8)*($X$3:$X$30=X8)*($Y$3:$Y$30=Y8)*($Z$3:$Z$30=Z8)*($AA$3:$AA$30>AA8)),"") -> 0 | AZ8: =IF(B8<>"",SUMPRODUCT(($E$3:$E$30=E8)*($F$3:$F$30=F8)*($G$3:$G$30=G8)*($H$3:$H$30=H8)*($I$3:$I$30=I8)*($J$3:$J$30=J8)*($K$3:$K$30=K8)*($L$3:$L$30=L8)*($M$3:$M$30=M8)*($N$3:$N$30=N8)*($O$3:$O$30=O8)*($P$3:$P$30=P8)*($Q$3:$Q$30=Q8)*($R$3:$R$30=R8)*($S$3:$S$30=S8)*($T$3:$T$30=T8)*($U$3:$U$30=U8)*($V$3:$V$30=V8)*($W$3:$W$30=W8)*($X$3:$X$30=X8)*($Y$3:$Y$30=Y8)*($Z$3:$Z$30=Z8)*($AA$3:$AA$30=AA8)*($AB$3:$AB$30>AB8)),"") -> 0 | BA8: =IF(B8<>"",SUMPRODUCT(($E$3:$E$30=E8)*($F$3:$F$30=F8)*($G$3:$G$30=G8)*($H$3:$H$30=H8)*($I$3:$I$30=I8)*($J$3:$J$30=J8)*($K$3:$K$30=K8)*($L$3:$L$30=L8)*($M$3:$M$30=M8)*($N$3:$N$30=N8)*($O$3:$O$30=O8)*($P$3:$P$30=P8)*($Q$3:$Q$30=Q8)*($R$3:$R$30=R8)*($S$3:$S$30=S8)*($T$3:$T$30=T8)*($U$3:$U$30=U8)*($V$3:$V$30=V8)*($W$3:$W$30=W8)*($X$3:$X$30=X8)*($Y$3:$Y$30=Y8)*($Z$3:$Z$30=Z8)*($AA$3:$AA$30=AA8)*($AB$3:$AB$30=AB8)*($AC$3:$AC$30>AC8)),"") -> 0 | BB8: =IF(B8<>"",SUMPRODUCT(($E$3:$E$30=E8)*($F$3:$F$30=F8)*($G$3:$G$30=G8)*($H$3:$H$30=H8)*($I$3:$I$30=I8)*($J$3:$J$30=J8)*($K$3:$K$30=K8)*($L$3:$L$30=L8)*($M$3:$M$30=M8)*($N$3:$N$30=N8)*($O$3:$O$30=O8)*($P$3:$P$30=P8)*($Q$3:$Q$30=Q8)*($R$3:$R$30=R8)*($S$3:$S$30=S8)*($T$3:$T$30=T8)*($U$3:$U$30=U8)*($V$3:$V$30=V8)*($W$3:$W$30=W8)*($X$3:$X$30=X8)*($Y$3:$Y$30=Y8)*($Z$3:$Z$30=Z8)*($AA$3:$AA$30=AA8)*($AB$3:$AB$30=AB8)*($AC$3:$AC$30=AC8)*($BC$3:$BC$30<BC8)),"") -> 0 | BC8: =IF(B8<>"",'Equipes e Pilotos'!B8,"") -> 6
